Workbook

Sheet CAPEX
A1: Cost factors
A2: Equipment erection | B2: fer | C2: 0.3
A3: Piping | B3: fp | C3: 0.8
A4: Instrumentation and control | B4: fi | C4: 0.3
A5: Electrical | B5: fel | C5: 0.2
A6: Civil | B6: fc | C6: 0.3
A7: Structures and buildings | B7: fs | C7: 0.2
A8: Lagging and paint | B8: fl | C8: 0.1
A9: Material factor for 304 SS | B9: fm | C9: 1.3
A12: Equipment | B12: Equipment approximated as | C12: Dimension needed | D12: Value | E12: a | F12: b | G12: n | H12: Purchased Cost (Ce,i,a) | J12: Equipment | K12: Internal diameter (m) | L12: h (m) | M12: External diameter (m) | N12: Area for shell (m2) | O12: Volume | P12: Density (kg/m3) | Q12: Shell mass (kg)
A13: Compressors | J13: V-100 | K13: 1.6764 | L13: =4.7244+2*0.25*K13 -> 5.5626 | M13: =K13+0.0254 -> 1.7018 | N13: =PI()*(M13*M13-K13*K13)/4 -> 0.067392095 | O13: =N13*L13 -> 0.37487527 | P13: 8000 | Q13: =P13*O13 -> 2999.0021
A14: K-100 | B14: Centrifugal Compressor | C14: Power, kW | D14: 1366.5031 | E14: 580000 | F14: 20000 | G14: 0.6 | H14: =(E14+(F14*(D14^G14)))/1000000 -> 2.1019359 | J14: V-101 | K14: 1.3716 | L14: =3.6576+2*0.25*K14 -> 4.3434 | M14: =K14+0.0254 -> 1.397 | N14: =PI()*(M14*M14-K14*K14)/4 -> 0.055231115 | O14: =N14*L14 -> 0.23989083 | P14: 8000 | Q14: =P14*O14 -> 1919.1266
A15: K-101 | B15: Centrifugal Compressor | C15: Power, kW | D15: 518.80827 | E15: 580000 | F15: 20000 | G15: 0.6 | H15: =(E15+(F15*(D15^G15)))/1000000 -> 1.4312049 | J15: CRV-100 | K15: =K13 -> 1.6764 | L15: =L13 -> 5.5626 | M15: =K15+0.0254 -> 1.7018 | N15: =PI()*(M15*M15-K15*K15)/4 -> 0.067392095 | O15: =N15*L15 -> 0.37487527 | P15: 8000 | Q15: =P15*O15 -> 2999.0021
A16: Heat exchangers
A17: E-103 | B17: U Tube HEX | C17: Area | D17: =I17/J17 -> 298.77984 | E17: 28000 | F17: 54 | G17: 1.2 | H17: =(E17+(F17*(D17^G17)))/1000000*J17 -> 0.15688934 | I17: 597.55968 | J17: 2
A18: E-105 | B18: U Tube HEX | C18: Area | D18: =I18/J18 -> 499.27777 | E18: 28000 | F18: 54 | G18: 1.2 | H18: =(E18+(F18*(D18^G18)))/1000000*J18 -> 1.5783609 | I18: 6490.6111 | J18: 13
A19: E-102 | B19: U Tube HEX | C19: Area | D19: =I19/J19 -> 419.54922 | E19: 28000 | F19: 54 | G19: 1.2 | H19: =(E19+(F19*(D19^G19)))/1000000*J19 -> 0.83048944 | I19: 3356.3937 | J19: 8
A20: E-104 | B20: U Tube HEX | C20: Area | D20: =I20/J20 -> 286.42402 | E20: 28000 | F20: 54 | G20: 1.2 | H20: =(E20+(F20*(D20^G20)))/1000000*J20 -> 0.07595182 | I20: 286.42402 | J20: 1
A21: Reactors
A22: CRV-100 | B22: Pressure vessel | C22: Shell mass, kg | D22: =Q15 -> 2999.0021 | E22: 17400 | F22: 79 | G22: 0.85 | H22: =(E22+(F22*(D22^G22)))/1000000 -> 0.088694717
A23: Flash separators
A24: V-100 | B24: Pressure vessel | C24: Shell mass, kg | D24: =Q13 -> 2999.0021 | E24: 17400 | F24: 79 | G24: 0.85 | H24: =(E24+(F24*(D24^G24)))/1000000 -> 0.088694717
A25: V-101 | B25: Pressure vessel | C25: Shell mass, kg | D25: =Q14 -> 1919.1266 | E25: 17400 | F25: 79 | G25: 0.85 | H25: =(E25+(F25*(D25^G25)))/1000000 -> 0.066182626
H26: =SUM(H14:H25) -> 6.4184044
A27: CEPCI 2010 | B27: 532.9
A28: CEPCI 2019 | B28: 607.5
A29: CEPCI 2022 | B29: 816
A30: Purchased equipment cost 2019 | B30: =H26*B28/B27 -> 7.3169088
A31: Purchased equipment cost 2022 | B31: =H26*B29/B27 -> 9.8281441
B33: 2022
A34: Installed capital cost | B34: =(B31)*((1+C3)+(C2+C5+C4+C6+C7+C8)/C9)*C9 -> 36.757259
A35: Offsites (OS) | B35: =0.3*B34 -> 11.027178
A36: Design and Engineering (D&E) | B36: =0.3*SUM(B34:B35) -> 14.335331
A37: Contingency (X) | B37: =0.1*SUM(B34:B35) -> 4.7784437
A38: Fixed capital investment | B38: =B34*(1+0.3)*(1+0.3+0.1) -> 66.898212
A39: Working capital | B39: =B38*0.15 -> 10.034732
A40: Total investment | B40: =B38+B39 -> 76.932943
A41: Project lifetime | B41: 25
A42: Interest rate | B42: 0.12
A43: ACCR | B43: =(B42*((1+B42)^B41))/(((1+B42)^B41)-1) -> 0.12749997
...

Sheet Production costs
A3: 2022
A4: Description | B4: Assumption | C4: M$/year
A5: Labor costs
A6: Operating labor | B6: 9 shift positions, 9 operators/shift | C6: =50000*9*9/1000000 -> 4.05
A7: Supervision | B7: 25% of operating Labor | C7: =0.25*C6 -> 1.0125
A8: Direct overhead | B8: 45% of labor and supervision | C8: =0.45*(C6+C7) -> 2.278125
C9: =SUM(C6:C8) -> 7.340625
A10: Maintanance costs
A11: Maintanance | B11: 3% of the installed capital cost | C11: =0.03*CAPEX!B34 -> 1.1027178
C12: =C11 -> 1.1027178
A13: Overhead expenses
A14: Plant overhead | B14: 65% of labor and maintanace | C14: =0.65*(C6+C7+C8+C11) -> 5.4881728
A15: Tax & Insurance | B15: 2% of installed cost and offsites | C15: =0.02*(CAPEX!B34+CAPEX!B35) -> 0.95568874
C16: =SUM(C14:C15) -> 6.4438615
A17: Interest
A18: Interest on debit | B18: 6% of working capital | C18: =0.06*CAPEX!B39 -> 0.6020839
C19: =C18 -> 0.6020839
A20: Total fixed production costs | C20: =C9+C12+C16+C19 -> 15.489288

Sheet OPEX
B3: Material | C3: Unit | D3: Quantity | E3: Price 2022 ($/unit) | F3: 2022 costs | I3: Ammonia price | J3: 2022 | K3: 2050
B4: Raw material costs | I4: Fossil | J4: 728.17 | K4: =J4*596.2/550.8*596.2/550.8*596.2/550.8/(1+0.02)^30 -> 509.82573
B5: Oxygen | C5: ton/hr | D5: 0 | E5: 0 | F5: =D5*E5 -> 0 | I5: Wind | J5: 1366.03 | K5: 925.28
B6: Ammonia fossil | C6: ton/hr | D6: =30690.5025481741/1000 -> 30.690503 | E6: 728.17 | F6: =D6*E6 -> 22347.903 | G6: =F6/Summary!$C$23 -> 0.59594292
B7: Ammonia wind | C7: ton/hr | D7: =30690.5025481741/1000 -> 30.690503 | E7: 1366.03 | F7: =D7*E7 -> 41924.147 | G7: =F7/Summary!$C$23 -> 1.1179751
B8: Utility costs | I8: 2022
B9: Cooling water | C9: GJ/hr | D9: =169540876.715708/10^6 -> 169.54088 | E9: =0.38*C17/C16 -> 0.51041975 | F9: =D9*E9 -> 86.537012 | I9: Ammonia price | J9: Fossil | K9: Wind
B10: Electricity | C10: kWh | D10: 1885.3113 | E10: =69.6/1000*C17/C16 -> 0.093487407 | F10: =D10*E10 -> 176.25287 | I10: Low | J10: 668.49 | K10: 1024.96
B11: OPEX (fossil ammonia) | C11: M$/year | F11: =(F5+F6+F9+F10)/1000000*8000 -> 180.88554 | I11: High | J11: 789.66 | K11: 1742
B12: OPEX (wind ammonia) | C12: M$/year | F12: =(F5+F7+F9+F10)/1000000*8000 -> 337.4955
I13: 2050
B14: Reference Data | I14: Ammonia price | J14: Fossil | K14: Wind
B15: CEPCI 2018 | C15: 603.1 | I15: Low | J15: =K4*0.85 -> 433.35187 | K15: 658.84 | L15: 784.95693 | M15: 658.84
B16: CEPCI 2019 | C16: 607.5 | I16: High | J16: =K4*1.15 -> 586.29959 | K16: 1191.73 | L16: 1062.0006 | M16: 1191.73
B17: CEPCI 2022 | C17: 816

Sheet Summary
B2: Fossil ammonia 2022 | F2: Wind ammonia 2022
B3: Purchased equipment cost 2022 (M$/year) | C3: =CAPEX!B31 -> 9.8281441 | F3: Purchased equipment cost 2022 (M$/year) | G3: =C3 -> 9.8281441
B4: Installed capital cost | C4: =CAPEX!B34 -> 36.757259 | F4: Installed capital cost | G4: =C4 -> 36.757259
B5: Offsites (OS) | C5: =CAPEX!B35 -> 11.027178 | F5: Offsites (OS) | G5: =C5 -> 11.027178
B6: Design and engineering (D&E) | C6: =CAPEX!B36 -> 14.335331 | F6: Design and engineering (D&E) | G6: =C6 -> 14.335331
B7: Contingency (X) | C7: =CAPEX!B37 -> 4.7784437 | F7: Contingency (X) | G7: =C7 -> 4.7784437
B8: Fixed capital investment | C8: =CAPEX!B38 -> 66.898212 | F8: Fixed capital investment | G8: =C8 -> 66.898212
B9: Working capital | C9: =CAPEX!B39 -> 10.034732 | F9: Working capital | G9: =C9 -> 10.034732
B10: Total investment | C10: =CAPEX!B40 -> 76.932943 | F10: Total investment | G10: =C10 -> 76.932943
B11: Labor costs | C11: =SUM('Production costs'!B9) -> 0 | F11: Labor costs | G11: =C11 -> 0
B12: Maintanance costs | C12: =SUM('Production costs'!B12) -> 0 | F12: Maintanance costs | G12: =C12 -> 0
B13: Overhead expenses | C13: =SUM('Production costs'!B16) -> 0 | F13: Overhead expenses | G13: =C13 -> 0
B14: Interest | C14: =SUM('Production costs'!B19) -> 0 | F14: Interest | G14: =C14 -> 0
B15: Project lifetime | C15: 25 | F15: Project lifetime | G15: =C15 -> 25
B16: Interest rate | C16: 0.12 | F16: Interest rate | G16: =C16 -> 0.12
B17: ACCR | C17: 0.12749997 | F17: ACCR | G17: =C17 -> 0.12749997
B18: CAPEX (M$/year) | C18: =CAPEX!B45 -> 9.8089479 | F18: CAPEX (M$/year) | G18: =C18 -> 9.8089479
B19: Fixed production costs (M$/year) | C19: 0 | F19: Fixed production costs (M$/year) | G19: 0
B20: OPEX (M$/year) | C20: =OPEX!F11 -> 180.88554 | F20: OPEX (M$/year) | G20: =OPEX!F12 -> 337.4955
B21: Total expenses (M$/year) | C21: =(C18+C19+C20) -> 190.69449 | F21: Total expenses (M$/year) | G21: =(G18+G19+G20) -> 347.30444
B22: Total expenses ($/hr) | C22: =(C21)*1000000/8000 -> 23836.812 | F22: Total expenses ($/hr) | G22: =(G21)*1000000/8000 -> 43413.056
B23: Total product Produced (kg/hr) | C23: 37500.073 | F23: Total product Produced (kg/hr) | G23: 37500.073
B24: Cost per kg | C24: =C22/C23 -> 0.63564706 | F24: Cost per kg | G24: =G22/G23 -> 1.1576792
