Workbook

Sheet CAPEX
A1: Cost factors
A2: Equipment erection | B2: fer | C2: 0.3
A3: Piping | B3: fp | C3: 0.8
A4: Instrumentation and control | B4: fi | C4: 0.3
A5: Electrical | B5: fel | C5: 0.2
A6: Civil | B6: fc | C6: 0.3
A7: Structures and buildings | B7: fs | C7: 0.2
A8: Lagging and paint | B8: fl | C8: 0.1
A9: Material factor for 304 SS | B9: fm | C9: 1.3
A12: Equipment | B12: Equipment approximated as | C12: Dimension needed | D12: Value | E12: a | F12: b | G12: n | H12: Purchased Cost (Ce,i,a) | J12: Equipment | K12: Internal diameter (m) | L12: h (m) | M12: External diameter (m) | N12: Area for shell (m2) | O12: Volume | P12: Density (kg/m3) | Q12: Shell mass (kg)
A13: Compressors | J13: V-100 | K13: 1.8288 | L13: =4.572+2*0.25*K13 -> 5.4864 | M13: =K13+0.0254 -> 1.8542 | N13: =PI()*(M13*M13-K13*K13)/4 -> 0.073472584 | O13: =N13*L13 -> 0.40309999 | P13: 8000 | Q13: =P13*O13 -> 3224.7999
A14: K-100 | B14: Centrifugal Compressor | C14: Power, kW | D14: 1791.396 | E14: 580000 | F14: 20000 | G14: 0.6 | H14: =(E14+(F14*(D14^G14)))/1000000 -> 2.3703789 | J14: V-101 | K14: 1.8288 | L14: =3.6576+2*0.25*K14 -> 4.572 | M14: =K14+0.0254 -> 1.8542 | N14: =PI()*(M14*M14-K14*K14)/4 -> 0.073472584 | O14: =N14*L14 -> 0.33591666 | P14: 8000 | Q14: =P14*O14 -> 2687.3332
A15: K-101 | B15: Centrifugal Compressor | C15: Power, kW | D15: 676.19515 | E15: 580000 | F15: 20000 | G15: 0.6 | H15: =(E15+(F15*(D15^G15)))/1000000 -> 1.5778683 | J15: CRV-100 | K15: 1.8288 | L15: =4.572+2*0.25*K15 -> 5.4864 | M15: =K15+0.0254 -> 1.8542 | N15: =PI()*(M15*M15-K15*K15)/4 -> 0.073472584 | O15: =N15*L15 -> 0.40309999 | P15: 8000 | Q15: =P15*O15 -> 3224.7999
A16: Heat exchangers
A17: E-103 | B17: U Tube HEX | C17: Area | D17: =I17/J17 -> 491.75466 | E17: 28000 | F17: 54 | G17: 1.2 | H17: =(E17+(F17*(D17^G17)))/1000000*J17 -> 1.9156142 | I17: 7868.0745 | J17: 16
A18: E-103 | B18: U Tube HEX | C18: Area | D18: =I18/J18 -> 393.07392 | E18: 28000 | F18: 54 | G18: 1.2 | H18: =(E18+(F18*(D18^G18)))/1000000*J18 -> 0.19621447 | I18: 786.14784 | J18: 2
A19: E-103 | B19: U Tube HEX | C19: Area | D19: =I19/J19 -> 412.21845 | E19: 28000 | F19: 54 | G19: 1.2 | H19: =(E19+(F19*(D19^G19)))/1000000*J19 -> 1.022244 | I19: 4122.1845 | J19: 10
A20: Reactors
A21: CRV-100 | B21: Pressure vessel | C21: Shell mass, kg | D21: =Q15 -> 3224.7999 | E21: 17400 | F21: 79 | G21: 0.85 | H21: =(E21+(F21*(D21^G21)))/1000000 -> 0.093232338
A22: Flash separators
A23: V-100 | B23: Pressure vessel | C23: Shell mass, kg | D23: =Q13 -> 3224.7999 | E23: 17400 | F23: 79 | G23: 0.85 | H23: =(E23+(F23*(D23^G23)))/1000000 -> 0.093232338
A24: V-101 | B24: Pressure vessel | C24: Shell mass, kg | D24: =Q14 -> 2687.3332 | E24: 17400 | F24: 79 | G24: 0.85 | H24: =(E24+(F24*(D24^G24)))/1000000 -> 0.082345698
H25: =SUM(H14:H24) -> 7.3511303
A26: CEPCI 2010 | B26: 532.9
A27: CEPCI 2019 | B27: 607.5
A28: CEPCI 2022 | B28: 816
A29: Purchased equipment cost 2019 | B29: =H25*B27/B26 -> 8.3802057
A30: Purchased equipment cost 2022 | B30: =H25*B28/B26 -> 11.256375
B32: 2019 | C32: 2022
A33: Installed capital cost | B33: =(B29)*((1+C3)+(C2+C5+C4+C6+C7+C8)/C9)*C9 -> 31.341969 | C33: =(B30)*((1+C3)+(C2+C5+C4+C6+C7+C8)/C9)*C9 -> 42.098843
A34: Offsites (OS) | B34: =0.3*B33 -> 9.4025908 | C34: =0.3*C33 -> 12.629653
A35: Design and Engineering (D&E) | B35: =0.3*SUM(B33:B34) -> 12.223368 | C35: =0.3*SUM(C33:C34) -> 16.418549
A36: Contingency (X) | B36: =0.1*SUM(B33:B34) -> 4.074456 | C36: =0.1*SUM(C33:C34) -> 5.4728496
A37: Fixed capital investment | B37: =B33*(1+0.3)*(1+0.3+0.1) -> 57.042384 | C37: =C33*(1+0.3)*(1+0.3+0.1) -> 76.619894
A38: Working capital | B38: =B37*0.15 -> 8.5563577 | C38: =C37*0.15 -> 11.492984
A39: Total investment | B39: =B37+B38 -> 65.598742 | C39: =C37+C38 -> 88.112878
A40: Project lifetime | B40: 25 | C40: 25
A41: Interest rate | B41: 0.12 | C41: 0.12
A42: ACCR | B42: =(B41*((1+B41)^B40))/(((1+B41)^B40)-1) -> 0.12749997 | C42: =(C41*((1+C41)^C40))/(((1+C41)^C40)-1) -> 0.12749997
A43: Annualized capital | B43: =B42*B39 -> 8.3638376 | C43: =C42*C39 -> 11.234389
...

Sheet Production costs
A3: 2019 | E3: 2022
A4: Description | B4: Assumption | C4: M$/year | E4: Description | F4: Assumption | G4: M$/year
A5: Labor costs | E5: Labor costs
A6: Operating labor | B6: 9 shift positions, 9 operators/shift | C6: =50000*9*9/1000000 -> 4.05 | E6: Operating labor | F6: 9 shift positions, 9 operators/shift | G6: =50000*9*9/1000000 -> 4.05
A7: Supervision | B7: 25% of operating Labor | C7: =0.25*C6 -> 1.0125 | E7: Supervision | F7: 25% of operating Labor | G7: =0.25*G6 -> 1.0125
A8: Direct overhead | B8: 45% of labor and supervision | C8: =0.45*(C6+C7) -> 2.278125 | E8: Direct overhead | F8: 45% of labor and supervision | G8: =0.45*(G6+G7) -> 2.278125
C9: =SUM(C6:C8) -> 7.340625 | G9: =SUM(G6:G8) -> 7.340625
A10: Maintanance costs | E10: Maintanance costs
A11: Maintanance | B11: 3% of the installed capital cost | C11: =0.03*CAPEX!B33 -> 0.94025908 | E11: Maintanance | F11: 3% of the installed capital cost | G11: =0.03*CAPEX!C33 -> 1.2629653
C12: =C11 -> 0.94025908 | G12: =G11 -> 1.2629653
A13: Overhead expenses | E13: Overhead expenses
A14: Plant overhead | B14: 65% of labor and maintanace | C14: =0.65*(C6+C7+C8+C11) -> 5.3825747 | E14: Plant overhead | F14: 65% of labor and maintanace | G14: =0.65*(G6+G7+G8+G11) -> 5.5923337
A15: Tax & Insurance | B15: 2% of installed cost and offsites | C15: =0.02*(CAPEX!B33+CAPEX!B34) -> 0.81489121 | E15: Tax & Insurance | F15: 2% of installed cost and offsites | G15: =0.02*(CAPEX!C33+CAPEX!C34) -> 1.0945699
C16: =SUM(C14:C15) -> 6.1974659 | G16: =SUM(G14:G15) -> 6.6869036
A17: Interest | E17: Interest
A18: Interest on debit | B18: 6% of working capital | C18: =0.06*CAPEX!B38 -> 0.51338146 | E18: Interest on debit | F18: 6% of working capital | G18: =0.06*CAPEX!C38 -> 0.68957905
C19: =C18 -> 0.51338146 | G19: =G18 -> 0.68957905
A20: Total fixed production costs | C20: =C9+C12+C16+C19 -> 14.991731 | E20: Total fixed production costs | G20: =G9+G12+G16+G19 -> 15.980073

Sheet OPEX
B3: Material | C3: Unit | D3: Quantity | E3: Price 2019 ($/unit) | F3: Price 2022 ($/unit) | G3: 2019 costs | H3: 2022 costs
B4: Raw material costs
B5: Oxygen | C5: ton/hr | D5: 0 | E5: =123.25*C17/C16 -> 124.14919 | F5: =E5*C18/C17 -> 166.75841 | G5: =D5*E5 -> 0 | H5: =D5*F5 -> 0 | I5: =G5/Summary!$C$23 -> 0 | J5: =H5/Summary!$C$23 -> 0
B6: Ammonia fossil | C6: ton/hr | D6: =36320.0422825098/1000 -> 36.320042 | E6: 465.07 | F6: 728.17 | G6: =D6*E6 -> 16891.362 | H6: =D6*F6 -> 26447.165 | I6: =G6/Summary!$C$23 -> 0.45043751 | J6: =H6/Summary!$C$23 -> 0.7052596
B7: Ammonia wind | C7: ton/hr | D7: =36320.0422825098/1000 -> 36.320042 | E7: 1313.2 | F7: 1366.03 | G7: =D7*E7 -> 47695.48 | H7: =D7*F7 -> 49614.267 | I7: =G7/Summary!$C$23 -> 1.2718828 | J7: =H7/Summary!$C$23 -> 1.3230506
B8: Utility costs
B9: Cooling water | C9: GJ/hr | D9: =198825004.077851/1000000 -> 198.825 | E9: 0.38 | F9: =E9*C18/C17 -> 0.51041975 | G9: =D9*E9 -> 75.553502 | H9: =D9*F9 -> 101.48421 | I9: =G9/Summary!$C$23 -> 0.0020147654 | J9: =H9/Summary!$C$23 -> 0.0027062527
B10: Natural gas | C10: ton/hr | D10: 0 | E10: 67.83 | F10: 288.06 | G10: =D10*E10 -> 0 | H10: =D10*F10 -> 0 | I10: =G10/Summary!$C$23 -> 0 | J10: =H10/Summary!$C$23 -> 0
B11: Electricity | C11: kWh | D11: 2467.5912 | E11: 0.06783 | F11: 0.0853 | G11: =D11*E11 -> 167.37671 | H11: =D11*F11 -> 210.48553 | I11: =G11/Summary!$C$23 -> 0.0044633907 | J11: =H11/Summary!$C$23 -> 0.0056129622
B12: OPEX (fossil ammonia) | C12: M$/year | G12: =(G5+G6+G9+G10+G11)/1000000*8000 -> 137.07434 | H12: =(H5+H6+H9+H10+H11)/1000000*8000 -> 214.07308
B13: OPEX (wind ammonia) | C13: M$/year | G13: =(G5+G7+G9+G10+G11)/1000000*8000 -> 383.50728 | H13: =(H5+H7+H9+H10+H11)/1000000*8000 -> 399.4099
B15: Reference Data
B16: CEPCI 2018 | C16: 603.1
B17: CEPCI 2019 | C17: 607.5
B18: CEPCI 2022 | C18: 816

Sheet Summary
B2: Fossil ammonia 2019 | E2: Fossil ammonia 2022 | H2: Wind ammonia 2019 | K2: Wind ammonia 2022
B3: Purchased equipment cost 2019 (M$/year) | C3: =SUM(CAPEX!B29) -> 8.3802057 | E3: Purchased equipment cost 2022 (M$/year) | F3: =CAPEX!B30 -> 11.256375 | H3: Purchased equipment cost 2019 (M$/year) | I3: =C3 -> 8.3802057 | K3: Purchased equipment cost 2022 (M$/year) | L3: =F3 -> 11.256375
B4: Installed capital cost | C4: =SUM(CAPEX!B33) -> 31.341969 | E4: Installed capital cost | F4: =CAPEX!C33 -> 42.098843 | H4: Installed capital cost | I4: =C4 -> 31.341969 | K4: Installed capital cost | L4: =F4 -> 42.098843
B5: Offsites (OS) | C5: =SUM(CAPEX!B34) -> 9.4025908 | E5: Offsites (OS) | F5: =CAPEX!C34 -> 12.629653 | H5: Offsites (OS) | I5: =C5 -> 9.4025908 | K5: Offsites (OS) | L5: =F5 -> 12.629653
B6: Design and engineering (D&E) | C6: =SUM(CAPEX!B35) -> 12.223368 | E6: Design and engineering (D&E) | F6: =CAPEX!C35 -> 16.418549 | H6: Design and engineering (D&E) | I6: =C6 -> 12.223368 | K6: Design and engineering (D&E) | L6: =F6 -> 16.418549
B7: Contingency (X) | C7: =SUM(CAPEX!B36) -> 4.074456 | E7: Contingency (X) | F7: =CAPEX!C36 -> 5.4728496 | H7: Contingency (X) | I7: =C7 -> 4.074456 | K7: Contingency (X) | L7: =F7 -> 5.4728496
B8: Fixed capital investment | C8: =SUM(CAPEX!B37) -> 57.042384 | E8: Fixed capital investment | F8: =CAPEX!C37 -> 76.619894 | H8: Fixed capital investment | I8: =C8 -> 57.042384 | K8: Fixed capital investment | L8: =F8 -> 76.619894
B9: Working capital | C9: =SUM(CAPEX!B38) -> 8.5563577 | E9: Working capital | F9: =CAPEX!C38 -> 11.492984 | H9: Working capital | I9: =C9 -> 8.5563577 | K9: Working capital | L9: =F9 -> 11.492984
B10: Total investment | C10: =SUM(CAPEX!B39) -> 65.598742 | E10: Total investment | F10: =CAPEX!C39 -> 88.112878 | H10: Total investment | I10: =C10 -> 65.598742 | K10: Total investment | L10: =F10 -> 88.112878
B11: Labor costs | C11: 0 | E11: Labor costs | F11: =SUM('Production costs'!F9) -> 0 | H11: Labor costs | I11: =C11 -> 0 | K11: Labor costs | L11: =F11 -> 0
B12: Maintanance costs | C12: 0 | E12: Maintanance costs | F12: =SUM('Production costs'!F12) -> 0 | H12: Maintanance costs | I12: =C12 -> 0 | K12: Maintanance costs | L12: =F12 -> 0
B13: Overhead expenses | C13: 0 | E13: Overhead expenses | F13: =SUM('Production costs'!F16) -> 0 | H13: Overhead expenses | I13: =C13 -> 0 | K13: Overhead expenses | L13: =F13 -> 0
B14: Interest | C14: 0 | E14: Interest | F14: =SUM('Production costs'!F19) -> 0 | H14: Interest | I14: =C14 -> 0 | K14: Interest | L14: =F14 -> 0
B15: Project lifetime | C15: =SUM(CAPEX!B40) -> 25 | E15: Project lifetime | F15: 25 | H15: Project lifetime | I15: =C15 -> 25 | K15: Project lifetime | L15: =F15 -> 25
B16: Interest rate | C16: =SUM(CAPEX!B41) -> 0.12 | E16: Interest rate | F16: 0.12 | H16: Interest rate | I16: =C16 -> 0.12 | K16: Interest rate | L16: =F16 -> 0.12
B17: ACCR | C17: =SUM(CAPEX!B42) -> 0.12749997 | E17: ACCR | F17: 0.12749997 | H17: ACCR | I17: =C17 -> 0.12749997 | K17: ACCR | L17: =F17 -> 0.12749997
B18: CAPEX (M$/year) | C18: =SUM(CAPEX!B44) -> 8.3638376 | E18: CAPEX (M$/year) | F18: =CAPEX!C44 -> 11.234389 | H18: CAPEX (M$/year) | I18: =C18 -> 8.3638376 | K18: CAPEX (M$/year) | L18: =F18 -> 11.234389
B19: Fixed production costs (M$/year) | C19: 0 | E19: Fixed production costs (M$/year) | F19: 0 | H19: Fixed production costs (M$/year) | I19: 0 | K19: Fixed production costs (M$/year) | L19: 0
B20: OPEX (M$/year) | C20: =OPEX!G12 -> 137.07434 | E20: OPEX (M$/year) | F20: =OPEX!H12 -> 214.07308 | H20: OPEX (M$/year) | I20: =OPEX!G13 -> 383.50728 | K20: OPEX (M$/year) | L20: =OPEX!H13 -> 399.4099
B21: Total expenses (M$/year) | C21: =(C18+C19+C20) -> 145.43818 | E21: Total expenses (M$/year) | F21: =(F18+F19+F20) -> 225.30747 | H21: Total expenses (M$/year) | I21: =(I18+I19+I20) -> 391.87112 | K21: Total expenses (M$/year) | L21: =(L18+L19+L20) -> 410.64429
B22: Total expenses ($/hr) | C22: =(C21)*1000000/8000 -> 18179.772 | E22: Total expenses ($/hr) | F22: =(F21)*1000000/8000 -> 28163.434 | H22: Total expenses ($/hr) | I22: =(I21)*1000000/8000 -> 48983.889 | K22: Total expenses ($/hr) | L22: =(L21)*1000000/8000 -> 51330.536
B23: Total product Produced (kg/hr) | C23: 37499.901 | E23: Total product Produced (kg/hr) | F23: =C23 -> 37499.901 | H23: Total product Produced (kg/hr) | I23: =F23 -> 37499.901 | K23: Total product Produced (kg/hr) | L23: =I23 -> 37499.901
B24: Cost per kg | C24: =C22/C23 -> 0.4847952 | E24: Cost per kg | F24: =F22/F23 -> 0.75102688 | H24: Cost per kg | I24: =I22/I23 -> 1.3062405 | K24: Cost per kg | L24: =L22/L23 -> 1.3688179
F26: =OPEX!H6/Summary!F23 -> 0.7052596 | I26: =I18*10^6/8000/I23 -> 0.027879532 | L26: =L18*10^6/8000/L23 -> 0.037448063
F27: =OPEX!H7/Summary!F23 -> 1.3230506
F28: =OPEX!H9/Summary!F23 -> 0.0027062527
F29: =OPEX!H10/Summary!F23 -> 0
F30: =OPEX!H11/Summary!F23 -> 0.0056129622
F31: =F18*10^6/8000/F23 -> 0.037448063
