Workbook

Sheet CAPEX
A1: Cost factors
A2: Equipment erection | B2: fer | C2: 0.3
A3: Piping | B3: fp | C3: 0.8
A4: Instrumentation and control | B4: fi | C4: 0.3
A5: Electrical | B5: fel | C5: 0.2
A6: Civil | B6: fc | C6: 0.3
A7: Structures and buildings | B7: fs | C7: 0.2
A8: Lagging and paint | B8: fl | C8: 0.1
A9: Material factor for 304 SS | B9: fm | C9: 1.3
A12: Equipment | B12: Equipment approximated as | C12: Dimension needed | D12: Value | E12: a | F12: b | G12: n | H12: Purchased Cost (Ce,i,a) | J12: Equipment | K12: Internal diameter (m) | L12: h (m) | M12: External diameter (m) | N12: Area for shell (m2) | O12: Volume | P12: Density (kg/m3) | Q12: Shell mass (kg)
A13: Compressors | J13: V-100 | K13: 4.1148 | L13: =3.6576+2*0.25*K13 -> 5.715 | M13: =K13+0.0254 -> 4.1402 | N13: =PI()*(M13*M13-K13*K13)/4 -> 0.16467993 | O13: =N13*L13 -> 0.9411458 | P13: 8000 | Q13: =P13*O13 -> 7529.1664
A14: K-100 | B14: Centrifugal Compressor | C14: Power, kW | D14: 12404.501 | E14: 580000 | F14: 20000 | G14: 0.6 | H14: =(E14+(F14*(D14^G14)))/1000000 -> 6.2971235 | J14: V-101 | K14: 1.3716 | L14: =3.6576+2*0.25*K14 -> 4.3434 | M14: =K14+0.0254 -> 1.397 | N14: =PI()*(M14*M14-K14*K14)/4 -> 0.055231115 | O14: =N14*L14 -> 0.23989083 | P14: 8000 | Q14: =P14*O14 -> 1919.1266
A15: K-101 | B15: Centrifugal Compressor | C15: Power, kW | D15: 5465.3973 | E15: 580000 | F15: 20000 | G15: 0.6 | H15: =(E15+(F15*(D15^G15)))/1000000 -> 4.0762545 | J15: V-102 | K15: 1.6764 | L15: =4.1148+2*0.25*K15 -> 4.953 | M15: =K15+0.0254 -> 1.7018 | N15: =PI()*(M15*M15-K15*K15)/4 -> 0.067392095 | O15: =N15*L15 -> 0.33379305 | P15: 8000 | Q15: =P15*O15 -> 2670.3444
A16: K-102 | B16: Centrifugal Compressor | C16: Power, kW | D16: 459.68808 | E16: 580000 | F16: 20000 | G16: 0.6 | H16: =(E16+(F16*(D16^G16)))/1000000 -> 1.3716039 | J16: V-103 | K16: 5.9436 | L16: =3.6576+2*0.25*K16 -> 6.6294 | M16: =K16+0.0254 -> 5.969 | N16: =PI()*(M16*M16-K16*K16)/4 -> 0.23764581 | O16: =N16*L16 -> 1.5754491 | P16: 8000 | Q16: =P16*O16 -> 12603.593
A17: K-103 | B17: Centrifugal Compressor | C17: Power, kW | D17: 207.32995 | E17: 580000 | F17: 20000 | G17: 0.6 | H17: =(E17+(F17*(D17^G17)))/1000000 -> 1.0709386 | J17: CRV-100 | K17: 0.9144 | L17: =3.9624+2*0.25*K17 -> 4.4196 | M17: =K17+0.0254 -> 0.9398 | N17: =PI()*(M17*M17-K17*K17)/4 -> 0.036989646 | O17: =N17*L17 -> 0.16347944 | P17: 8000 | Q17: =P17*O17 -> 1307.8355
A18: K-104 | B18: Centrifugal Compressor | C18: Power, kW | D18: 1359.2785 | E18: 580000 | F18: 20000 | G18: 0.6 | H18: =(E18+(F18*(D18^G18)))/1000000 -> 2.097103 | J18: CRV-101 | K18: 1.2192 | L18: =4.7244+2*0.25*K18 -> 5.334 | M18: =K18+0.0254 -> 1.2446 | N18: =PI()*(M18*M18-K18*K18)/4 -> 0.049150625 | O18: =N18*L18 -> 0.26216944 | P18: 8000 | Q18: =P18*O18 -> 2097.3555
A19: K-105 | B19: Centrifugal Compressor | C19: Power, kW | D19: 516.06536 | E19: 580000 | F19: 20000 | G19: 0.6 | H19: =(E19+(F19*(D19^G19)))/1000000 -> 1.4285019 | J19: CRV-102 | K19: 1.2192 | L19: =4.7244+2*0.25*K19 -> 5.334 | M19: =K19+0.0254 -> 1.2446 | N19: =PI()*(M19*M19-K19*K19)/4 -> 0.049150625 | O19: =N19*L19 -> 0.26216944 | P19: 8000 | Q19: =P19*O19 -> 2097.3555
A20: Pumps
A21: P-100 | B21: Centrifugal Pump | C21: Flow, litres/s | D21: 5.034669 | E21: 8000 | F21: 240 | G21: 0.9 | H21: =(E21+(F21*(D21^G21)))/1000000 -> 0.009027981
A22: Heat exchangers
A23: E-103 | B23: U Tube HEX | C23: Area | D23: =I23/J23 -> 485.73072 | E23: 28000 | F23: 54 | G23: 1.2 | H23: =(E23+(F23*(D23^G23)))/1000000*J23 -> 0.71027514 | I23: 2914.3843 | J23: 6
A24: E-103 | B24: U Tube HEX | C24: Area | D24: =I24/J24 -> 151.16441 | E24: 28000 | F24: 54 | G24: 1.2 | H24: =(E24+(F24*(D24^G24)))/1000000*J24 -> 0.050270667 | I24: 151.16441 | J24: 1
A25: E-103 | B25: U Tube HEX | C25: Area | D25: =I25/J25 -> 142.25914 | E25: 28000 | F25: 54 | G25: 1.2 | H25: =(E25+(F25*(D25^G25)))/1000000*J25 -> 0.048705702 | I25: 142.25914 | J25: 1
A26: E-103 | B26: U Tube HEX | C26: Area | D26: =I26/J26 -> 57.827471 | E26: 28000 | F26: 54 | G26: 1.2 | H26: =(E26+(F26*(D26^G26)))/1000000*J26 -> 0.035029992 | I26: 57.827471 | J26: 1
A27: E-103 | B27: U Tube HEX | C27: Area | D27: =I27/J27 -> 413.60541 | E27: 28000 | F27: 54 | G27: 1.2 | H27: =(E27+(F27*(D27^G27)))/1000000*J27 -> 0.41009672 | I27: 1654.4216 | J27: 4
A28: E-103 | B28: U Tube HEX | C28: Area | D28: =I28/J28 -> 376.42109 | E28: 28000 | F28: 54 | G28: 1.2 | H28: =(E28+(F28*(D28^G28)))/1000000*J28 -> 0.37823337 | I28: 1505.6844 | J28: 4
A29: E-103 | B29: U Tube HEX | C29: Area | D29: =I29/J29 -> 486.06163 | E29: 28000 | F29: 54 | G29: 1.2 | H29: =(E29+(F29*(D29^G29)))/1000000*J29 -> 0.94762466 | I29: 3888.4931 | J29: 8
A30: E-103 | B30: U Tube HEX | C30: Area | D30: =I30/J30 -> 232.65318 | E30: 28000 | F30: 54 | G30: 1.2 | H30: =(E30+(F30*(D30^G30)))/1000000*J30 -> 0.065363241 | I30: 232.65318 | J30: 1
A31: E-103 | B31: U Tube HEX | C31: Area | D31: =I31/J31 -> 88.607223 | E31: 28000 | F31: 54 | G31: 1.2 | H31: =(E31+(F31*(D31^G31)))/1000000*J31 -> 0.079463171 | I31: 177.21445 | J31: 2
A32: E-105 | B32: U Tube HEX | C32: Area | D32: =I32/J32 -> 98.872764 | E32: 28000 | F32: 54 | G32: 1.2 | H32: =(E32+(F32*(D32^G32)))/1000000*J32 -> 0.082761827 | I32: 197.74553 | J32: 2
A33: E-106 | B33: U Tube HEX | C33: Area | D33: =I33/J33 -> 484.51369 | E33: 28000 | F33: 54 | G33: 1.2 | H33: =(E33+(F33*(D33^G33)))/1000000*J33 -> 1.7716128 | I33: 7267.7054 | J33: 15
A34: E-107 | B34: U Tube HEX | C34: Area | D34: =I34/J34 -> 475.84189 | E34: 28000 | F34: 54 | G34: 1.2 | H34: =(E34+(F34*(D34^G34)))/1000000*J34 -> 2.3235142 | I34: 9516.8378 | J34: 20
... A38: E-102 | B38: U Tube HEX | C38: Area | D38: =I38/J38 -> 375.05311 | E38: 28000 | F38: 54 | G38: 1.2 | H38: =(E38+(F38*(D38^G38)))/1000000*J38 -> 0.094268187 | I38: 375.05311 | J38: 1
A39: Reactors
A40: CRV-100 | B40: Pressure vessel | C40: Shell mass, kg | D40: =Q17 -> 1307.8355 | E40: 17400 | F40: 79 | G40: 0.85 | H40: =(E40+(F40*(D40^G40)))/1000000 -> 0.052612532
A41: CRV-101 | B41: Pressure vessel | C41: Shell mass, kg | D41: =Q18 -> 2097.3555 | E41: 17400 | F41: 79 | G41: 0.85 | H41: =(E41+(F41*(D41^G41)))/1000000 -> 0.070007581
A42: CRV-102 | B42: Pressure vessel | C42: Shell mass, kg | D42: =Q19 -> 2097.3555 | E42: 17400 | F42: 79 | G42: 0.85 | H42: =(E42+(F42*(D42^G42)))/1000000 -> 0.070007581
A43: Flash separators
A44: V-100 | B44: Pressure vessel | C44: Shell mass, kg | D44: =Q13 -> 7529.1664 | E44: 17400 | F44: 79 | G44: 0.85 | H44: =(E44+(F44*(D44^G44)))/1000000 -> 0.17330569
A45: V-101 | B45: Pressure vessel | C45: Shell mass, kg | D45: =Q14 -> 1919.1266 | E45: 17400 | F45: 79 | G45: 0.85 | H45: =(E45+(F45*(D45^G45)))/1000000 -> 0.066182626
...

Sheet Production costs
A3: 2019 | E3: 2022
A4: Description | B4: Assumption | C4: M$/year | E4: Description | F4: Assumption | G4: M$/year
A5: Labor costs | E5: Labor costs
A6: Operating labor | B6: 9 shift positions, 9 operators/shift | C6: =50000*9*9/1000000 -> 4.05 | E6: Operating labor | F6: 9 shift positions, 9 operators/shift | G6: =50000*9*9/1000000 -> 4.05
A7: Supervision | B7: 25% of operating Labor | C7: =0.25*C6 -> 1.0125 | E7: Supervision | F7: 25% of operating Labor | G7: =0.25*G6 -> 1.0125
A8: Direct overhead | B8: 45% of labor and supervision | C8: =0.45*(C6+C7) -> 2.278125 | E8: Direct overhead | F8: 45% of labor and supervision | G8: =0.45*(G6+G7) -> 2.278125
C9: =SUM(C6:C8) -> 7.340625 | G9: =SUM(G6:G8) -> 7.340625
A10: Maintanance costs | E10: Maintanance costs
A11: Maintanance | B11: 3% of the installed capital cost | C11: =0.03*CAPEX!B56 -> 3.4844381 | E11: Maintanance | F11: 3% of the installed capital cost | G11: =0.03*CAPEX!C56 -> 4.6803316
C12: =C11 -> 3.4844381 | G12: =G11 -> 4.6803316
A13: Overhead expenses | E13: Overhead expenses
A14: Plant overhead | B14: 65% of labor and maintanace | C14: =0.65*(C6+C7+C8+C11) -> 7.036291 | E14: Plant overhead | F14: 65% of labor and maintanace | G14: =0.65*(G6+G7+G8+G11) -> 7.8136218
A15: Tax & Insurance | B15: 2% of installed cost and offsites | C15: =0.02*(CAPEX!B56+CAPEX!B57) -> 3.0198463 | E15: Tax & Insurance | F15: 2% of installed cost and offsites | G15: =0.02*(CAPEX!C56+CAPEX!C57) -> 4.0562874
C16: =SUM(C14:C15) -> 10.056137 | G16: =SUM(G14:G15) -> 11.869909
A17: Interest | E17: Interest
A18: Interest on debit | B18: 6% of working capital | C18: =0.06*CAPEX!B61 -> 1.9025032 | E18: Interest on debit | F18: 6% of working capital | G18: =0.06*CAPEX!C61 -> 2.5554611
C19: =C18 -> 1.9025032 | G19: =G18 -> 2.5554611
A20: Total fixed production costs | C20: =C9+C12+C16+C19 -> 22.783704 | E20: Total fixed production costs | G20: =G9+G12+G16+G19 -> 26.446327

Sheet OPEX
B3: Material | C3: Unit | D3: Quantity | E3: Price 2019 ($/unit) | F3: Price 2022 ($/unit) | G3: 2019 costs | H3: 2022 costs
B4: Raw material costs
B5: Oxygen | C5: ton/hr | D5: 0 | E5: =123.25*C17/C16 -> 124.14919 | F5: =E5*C18/C17 -> 166.75841 | G5: =D5*E5 -> 0 | H5: =D5*F5 -> 0 | I5: =G5/Summary!$C$23 -> 0 | J5: =H5/Summary!$C$23 -> 0
B6: Ammonia fossil | C6: ton/hr | D6: =33362.86704/1000 -> 33.362867 | E6: 465.07 | F6: 728.17 | G6: =D6*E6 -> 15516.069 | H6: =D6*F6 -> 24293.839 | I6: =G6/Summary!$C$23 -> 0.41596017 | J6: =H6/Summary!$C$23 -> 0.65127769
B7: Ammonia wind | C7: ton/hr | D7: =33362.86704/1000 -> 33.362867 | E7: 1313.2 | F7: 1366.03 | G7: =D7*E7 -> 43812.117 | H7: =D7*F7 -> 45574.677 | I7: =G7/Summary!$C$23 -> 1.1745305 | J7: =H7/Summary!$C$23 -> 1.2217818
B8: Utility costs
B9: Cooling water | C9: GJ/hr | D9: =155874111.740109/10^6 -> 155.87411 | E9: 0.38 | F9: =E9*C18/C17 -> 0.51041975 | G9: =D9*E9 -> 59.232162 | H9: =D9*F9 -> 79.561226 | I9: =G9/Summary!$C$23 -> 0.0015879164 | J9: =H9/Summary!$C$23 -> 0.002132905
B10: Natural gas | C10: ton/hr | D10: =222.373964161042/1000 -> 0.22237396 | E10: 67.83 | F10: 288.06 | G10: =D10*E10 -> 15.083626 | H10: =D10*F10 -> 64.057044 | I10: =G10/Summary!$C$23 -> 0.00040436709 | J10: =H10/Summary!$C$23 -> 0.0017172635
B11: Electricity | C11: kWh | D11: 20416.406 | E11: 0.06783 | F11: 0.0853 | G11: =D11*E11 -> 1384.8448 | H11: =D11*F11 -> 1741.5195 | I11: =G11/Summary!$C$23 -> 0.037125402 | J11: =H11/Summary!$C$23 -> 0.04668726
B12: OPEX (fossil ammonia) | C12: M$/year | G12: =(G5+G6+G9+G10+G11)/1000000*8000 -> 135.80183 | H12: =(H5+H6+H9+H10+H11)/1000000*8000 -> 209.43181
B13: OPEX (wind ammonia) | C13: M$/year | G13: =(G5+G7+G9+G10+G11)/1000000*8000 -> 362.17022 | H13: =(H5+H7+H9+H10+H11)/1000000*8000 -> 379.67852
B15: Reference Data
B16: CEPCI 2018 | C16: 603.1
B17: CEPCI 2019 | C17: 607.5
B18: CEPCI 2022 | C18: 816

Sheet Summary
B2: Fossil ammonia 2019 | E2: Fossil ammonia 2022 | H2: Wind ammonia 2019 | K2: Wind ammonia 2022
B3: Purchased equipment cost 2019 (M$/year) | C3: =SUM(CAPEX!B52) -> 31.055598 | E3: Purchased equipment cost 2022 (M$/year) | F3: =CAPEX!B53 -> 41.714185 | H3: Purchased equipment cost 2019 (M$/year) | I3: =C3 -> 31.055598 | K3: Purchased equipment cost 2022 (M$/year) | L3: =F3 -> 41.714185
B4: Installed capital cost | C4: =SUM(CAPEX!B56) -> 116.14794 | E4: Installed capital cost | F4: =CAPEX!C56 -> 156.01105 | H4: Installed capital cost | I4: =C4 -> 116.14794 | K4: Installed capital cost | L4: =F4 -> 156.01105
B5: Offsites (OS) | C5: =SUM(CAPEX!B57) -> 34.844381 | E5: Offsites (OS) | F5: =CAPEX!C57 -> 46.803316 | H5: Offsites (OS) | I5: =C5 -> 34.844381 | K5: Offsites (OS) | L5: =F5 -> 46.803316
B6: Design and engineering (D&E) | C6: =SUM(CAPEX!B58) -> 45.297695 | E6: Design and engineering (D&E) | F6: =CAPEX!C58 -> 60.844311 | H6: Design and engineering (D&E) | I6: =C6 -> 45.297695 | K6: Design and engineering (D&E) | L6: =F6 -> 60.844311
B7: Contingency (X) | C7: =SUM(CAPEX!B59) -> 15.099232 | E7: Contingency (X) | F7: =CAPEX!C59 -> 20.281437 | H7: Contingency (X) | I7: =C7 -> 15.099232 | K7: Contingency (X) | L7: =F7 -> 20.281437
B8: Fixed capital investment | C8: =SUM(CAPEX!B60) -> 211.38924 | E8: Fixed capital investment | F8: =CAPEX!C60 -> 283.94012 | H8: Fixed capital investment | I8: =C8 -> 211.38924 | K8: Fixed capital investment | L8: =F8 -> 283.94012
B9: Working capital | C9: =SUM(CAPEX!B61) -> 31.708386 | E9: Working capital | F9: =CAPEX!C61 -> 42.591018 | H9: Working capital | I9: =C9 -> 31.708386 | K9: Working capital | L9: =F9 -> 42.591018
B10: Total investment | C10: =SUM(CAPEX!B62) -> 243.09763 | E10: Total investment | F10: =CAPEX!C62 -> 326.53114 | H10: Total investment | I10: =C10 -> 243.09763 | K10: Total investment | L10: =F10 -> 326.53114
B11: Labor costs | C11: 0 | E11: Labor costs | F11: =SUM('Production costs'!F9) -> 0 | H11: Labor costs | I11: =C11 -> 0 | K11: Labor costs | L11: =F11 -> 0
B12: Maintanance costs | C12: 0 | E12: Maintanance costs | F12: =SUM('Production costs'!F12) -> 0 | H12: Maintanance costs | I12: =C12 -> 0 | K12: Maintanance costs | L12: =F12 -> 0
B13: Overhead expenses | C13: 0 | E13: Overhead expenses | F13: =SUM('Production costs'!F16) -> 0 | H13: Overhead expenses | I13: =C13 -> 0 | K13: Overhead expenses | L13: =F13 -> 0
B14: Interest | C14: 0 | E14: Interest | F14: =SUM('Production costs'!F19) -> 0 | H14: Interest | I14: =C14 -> 0 | K14: Interest | L14: =F14 -> 0
B15: Project lifetime | C15: =SUM(CAPEX!B63) -> 25 | E15: Project lifetime | F15: 25 | H15: Project lifetime | I15: =C15 -> 25 | K15: Project lifetime | L15: =F15 -> 25
B16: Interest rate | C16: =SUM(CAPEX!B64) -> 0.12 | E16: Interest rate | F16: 0.12 | H16: Interest rate | I16: =C16 -> 0.12 | K16: Interest rate | L16: =F16 -> 0.12
B17: ACCR | C17: =SUM(CAPEX!B65) -> 0.12749997 | E17: ACCR | F17: 0.12749997 | H17: ACCR | I17: =C17 -> 0.12749997 | K17: ACCR | L17: =F17 -> 0.12749997
B18: CAPEX (M$/year) | C18: =SUM(CAPEX!B67) -> 30.99494 | E18: CAPEX (M$/year) | F18: =CAPEX!C67 -> 41.63271 | H18: CAPEX (M$/year) | I18: =C18 -> 30.99494 | K18: CAPEX (M$/year) | L18: =F18 -> 41.63271
B19: Fixed production costs (M$/year) | C19: 0 | E19: Fixed production costs (M$/year) | F19: 0 | H19: Fixed production costs (M$/year) | I19: 0 | K19: Fixed production costs (M$/year) | L19: 0
B20: OPEX (M$/year) | C20: =OPEX!G12 -> 135.80183 | E20: OPEX (M$/year) | F20: =OPEX!H12 -> 209.43181 | H20: OPEX (M$/year) | I20: =OPEX!G13 -> 362.17022 | K20: OPEX (M$/year) | L20: =OPEX!H13 -> 379.67852
B21: Total expenses (M$/year) | C21: =(C18+C19+C20) -> 166.79677 | E21: Total expenses (M$/year) | F21: =(F18+F19+F20) -> 251.06452 | H21: Total expenses (M$/year) | I21: =(I18+I19+I20) -> 393.16516 | K21: Total expenses (M$/year) | L21: =(L18+L19+L20) -> 421.31123
B22: Total expenses ($/hr) | C22: =(C21)*1000000/8000 -> 20849.597 | E22: Total expenses ($/hr) | F22: =(F21)*1000000/8000 -> 31383.065 | H22: Total expenses ($/hr) | I22: =(I21)*1000000/8000 -> 49145.645 | K22: Total expenses ($/hr) | L22: =(L21)*1000000/8000 -> 52663.904
B23: Total product Produced (kg/hr) | C23: 37301.814 | E23: Total product Produced (kg/hr) | F23: 37301.814 | H23: Total product Produced (kg/hr) | I23: 37301.814 | K23: Total product Produced (kg/hr) | L23: 37301.814
B24: Cost per kg | C24: =C22/C23 -> 0.55894324 | E24: Cost per kg | F24: =F22/F23 -> 0.84132814 | H24: Cost per kg | I24: =I22/I23 -> 1.3175136 | K24: Cost per kg | L24: =L22/L23 -> 1.4118323
I26: =I18*10^6/8000/I23 -> 0.10386539 | L26: =L18*10^6/8000/L23 -> 0.13951302
E28: Ammonia | F28: =OPEX!H6/Summary!C23 -> 0.65127769 | K28: Ammonia | L28: =OPEX!H7/Summary!L23 -> 1.2217818
E29: Electricity | F29: =OPEX!H11/Summary!F23 -> 0.04668726 | K29: Electricity | L29: =F29 -> 0.04668726
E30: Heating utilities | F30: =OPEX!H10/Summary!F23 -> 0.0017172635 | K30: Heating utilities | L30: =F30 -> 0.0017172635
E31: Cooling utilities | F31: =OPEX!H9/Summary!F23 -> 0.002132905 | K31: Cooling utilities | L31: =F31 -> 0.002132905
E32: CAPEX | F32: =F18*10^6/8000/F23 -> 0.13951302 | K32: CAPEX | L32: =F32 -> 0.13951302
F33: =SUM(F28:F32) -> 0.84132814 | L33: =SUM(L28:L32) -> 1.4118323
