Workbook

Sheet CAPEX
A1: Cost factors
A2: Equipment erection | B2: fer | C2: 0.3
A3: Piping | B3: fp | C3: 0.8
A4: Instrumentation and control | B4: fi | C4: 0.3
A5: Electrical | B5: fel | C5: 0.2
A6: Civil | B6: fc | C6: 0.3
A7: Structures and buildings | B7: fs | C7: 0.2
A8: Lagging and paint | B8: fl | C8: 0.1
A9: Material factor for 304 SS | B9: fm | C9: 1.3
A12: Equipment | B12: Equipment approximated as | C12: Dimension needed | D12: Value | E12: a | F12: b | G12: n | H12: Purchased Cost (Ce,i,a) | J12: Equipment | K12: Internal diameter (m) | L12: h (m) | M12: External diameter (m) | N12: Area for shell (m2) | O12: Volume | P12: Density (kg/m3) | Q12: Shell mass (kg)
A13: Compressors | J13: V-100 | K13: 8.6868 | L13: 30.4038 | M13: =K13+0.0254 -> 8.7122 | N13: =PI()*(M13*M13-K13*K13)/4 -> 0.34709462 | O13: =N13*L13 -> 10.552996 | P13: 8000 | Q13: =P13*O13 -> 84423.964
A14: K-102 | B14: Centrifugal Compressor | C14: Power, kW | D14: 13933.004 | E14: 580000 | F14: 20000 | G14: 0.6 | H14: =(E14+(F14*(D14^G14)))/1000000 -> 6.7099489 | J14: V-101 | K14: 7.4676 | L14: 26.1366 | M14: =K14+0.0254 -> 7.493 | N14: =PI()*(M14*M14-K14*K14)/4 -> 0.29845071 | O14: =N14*L14 -> 7.8004867 | P14: 8000 | Q14: =P14*O14 -> 62403.894
A15: K-103 | B15: Centrifugal Compressor | C15: Power, kW | D15: 5137.2427 | E15: 580000 | F15: 20000 | G15: 0.6 | H15: =(E15+(F15*(D15^G15)))/1000000 -> 3.9487443 | J15: CRV-100 | K15: 8.6868 | L15: 30.4038 | M15: =K15+0.0254 -> 8.7122 | N15: =PI()*(M15*M15-K15*K15)/4 -> 0.34709462 | O15: =N15*L15 -> 10.552996 | P15: 8000 | Q15: =P15*O15 -> 84423.964
A16: Heat exchangers
A17: E-104 | B17: U Tube HEX | C17: Area | D17: =2804.63450119857/3 -> 934.87817 | E17: 28000 | F17: 54 | G17: 1.2 | H17: =(E17+(F17*(D17^G17)))/1000000 -> 0.22628953
A18: E-104 | B18: U Tube HEX | C18: Area | D18: =2804.63450119857/3 -> 934.87817 | E18: 28000 | F18: 54 | G18: 1.2 | H18: =(E18+(F18*(D18^G18)))/1000000 -> 0.22628953
A19: E-104 | B19: U Tube HEX | C19: Area | D19: =2804.63450119857/3 -> 934.87817 | E19: 28000 | F19: 54 | G19: 1.2 | H19: =(E19+(F19*(D19^G19)))/1000000 -> 0.22628953
A20: E-105 | B20: U Tube HEX | C20: Area | D20: =10533.3291201941/11 -> 957.57537 | E20: 28000 | F20: 54 | G20: 1.2 | H20: =(E20+(F20*(D20^G20)))/1000000 -> 0.23208041
A21: E-105 | B21: U Tube HEX | C21: Area | D21: =10533.3291201941/11 -> 957.57537 | E21: 28000 | F21: 54 | G21: 1.2 | H21: =(E21+(F21*(D21^G21)))/1000000 -> 0.23208041
A22: E-105 | B22: U Tube HEX | C22: Area | D22: =10533.3291201941/11 -> 957.57537 | E22: 28000 | F22: 54 | G22: 1.2 | H22: =(E22+(F22*(D22^G22)))/1000000 -> 0.23208041
A23: E-105 | B23: U Tube HEX | C23: Area | D23: =10533.3291201941/11 -> 957.57537 | E23: 28000 | F23: 54 | G23: 1.2 | H23: =(E23+(F23*(D23^G23)))/1000000 -> 0.23208041
A24: E-105 | B24: U Tube HEX | C24: Area | D24: =10533.3291201941/11 -> 957.57537 | E24: 28000 | F24: 54 | G24: 1.2 | H24: =(E24+(F24*(D24^G24)))/1000000 -> 0.23208041
A25: E-105 | B25: U Tube HEX | C25: Area | D25: =10533.3291201941/11 -> 957.57537 | E25: 28000 | F25: 54 | G25: 1.2 | H25: =(E25+(F25*(D25^G25)))/1000000 -> 0.23208041
A26: E-105 | B26: U Tube HEX | C26: Area | D26: =10533.3291201941/11 -> 957.57537 | E26: 28000 | F26: 54 | G26: 1.2 | H26: =(E26+(F26*(D26^G26)))/1000000 -> 0.23208041
A27: E-105 | B27: U Tube HEX | C27: Area | D27: =10533.3291201941/11 -> 957.57537 | E27: 28000 | F27: 54 | G27: 1.2 | H27: =(E27+(F27*(D27^G27)))/1000000 -> 0.23208041
A28: E-105 | B28: U Tube HEX | C28: Area | D28: =10533.3291201941/11 -> 957.57537 | E28: 28000 | F28: 54 | G28: 1.2 | H28: =(E28+(F28*(D28^G28)))/1000000 -> 0.23208041
A29: E-105 | B29: U Tube HEX | C29: Area | D29: =10533.3291201941/11 -> 957.57537 | E29: 28000 | F29: 54 | G29: 1.2 | H29: =(E29+(F29*(D29^G29)))/1000000 -> 0.23208041
A30: E-105 | B30: U Tube HEX | C30: Area | D30: =10533.3291201941/11 -> 957.57537 | E30: 28000 | F30: 54 | G30: 1.2 | H30: =(E30+(F30*(D30^G30)))/1000000 -> 0.23208041
A31: E-106 | B31: U Tube HEX | C31: Area | D31: =2514.3159326678/3 -> 838.10531 | E31: 28000 | F31: 54 | G31: 1.2 | H31: =(E31+(F31*(D31^G31)))/1000000 -> 0.20192102
A32: E-106 | B32: U Tube HEX | C32: Area | D32: =2514.3159326678/3 -> 838.10531 | E32: 28000 | F32: 54 | G32: 1.2 | H32: =(E32+(F32*(D32^G32)))/1000000 -> 0.20192102
A33: E-106 | B33: U Tube HEX | C33: Area | D33: =2514.3159326678/3 -> 838.10531 | E33: 28000 | F33: 54 | G33: 1.2 | H33: =(E33+(F33*(D33^G33)))/1000000 -> 0.20192102
A34: E-107 | B34: U Tube HEX | C34: Area | D34: =2433.82633534085/3 -> 811.27545 | E34: 28000 | F34: 54 | G34: 1.2 | H34: =(E34+(F34*(D34^G34)))/1000000 -> 0.19526141
A35: E-107 | B35: U Tube HEX | C35: Area | D35: =2433.82633534085/3 -> 811.27545 | E35: 28000 | F35: 54 | G35: 1.2 | H35: =(E35+(F35*(D35^G35)))/1000000 -> 0.19526141
A36: E-107 | B36: U Tube HEX | C36: Area | D36: =2433.82633534085/3 -> 811.27545 | E36: 28000 | F36: 54 | G36: 1.2 | H36: =(E36+(F36*(D36^G36)))/1000000 -> 0.19526141
A37: E-108 | B37: U Tube HEX | C37: Area | D37: =2939.89130662255/3 -> 979.96377 | E37: 28000 | F37: 54 | G37: 1.2 | H37: =(E37+(F37*(D37^G37)))/1000000 -> 0.23781947
A38: E-108 | B38: U Tube HEX | C38: Area | D38: =2939.89130662255/3 -> 979.96377 | E38: 28000 | F38: 54 | G38: 1.2 | H38: =(E38+(F38*(D38^G38)))/1000000 -> 0.23781947
A39: E-108 | B39: U Tube HEX | C39: Area | D39: =2939.89130662255/3 -> 979.96377 | E39: 28000 | F39: 54 | G39: 1.2 | H39: =(E39+(F39*(D39^G39)))/1000000 -> 0.23781947
A40: E-109 | B40: U Tube HEX | C40: Area | D40: =3623.83504397306/4 -> 905.95876 | E40: 28000 | F40: 54 | G40: 1.2 | H40: =(E40+(F40*(D40^G40)))/1000000 -> 0.21895185
A41: E-109 | B41: U Tube HEX | C41: Area | D41: =3623.83504397306/4 -> 905.95876 | E41: 28000 | F41: 54 | G41: 1.2 | H41: =(E41+(F41*(D41^G41)))/1000000 -> 0.21895185
A42: E-109 | B42: U Tube HEX | C42: Area | D42: =3623.83504397306/4 -> 905.95876 | E42: 28000 | F42: 54 | G42: 1.2 | H42: =(E42+(F42*(D42^G42)))/1000000 -> 0.21895185
...

Sheet Production costs
A3: 2019 | E3: 2022
A4: Description | B4: Assumption | C4: M$/year | E4: Description | F4: Assumption | G4: M$/year
A5: Labor costs | E5: Labor costs
A6: Operating labor | B6: 9 shift positions, 9 operators/shift | C6: =50000*9*9/1000000 -> 4.05 | E6: Operating labor | F6: 9 shift positions, 9 operators/shift | G6: =50000*9*9/1000000 -> 4.05
A7: Supervision | B7: 25% of operating Labor | C7: =0.25*C6 -> 1.0125 | E7: Supervision | F7: 25% of operating Labor | G7: =0.25*G6 -> 1.0125
A8: Direct overhead | B8: 45% of labor and supervision | C8: =0.45*(C6+C7) -> 2.278125 | E8: Direct overhead | F8: 45% of labor and supervision | G8: =0.45*(G6+G7) -> 2.278125
C9: =SUM(C6:C8) -> 7.340625 | G9: =SUM(G6:G8) -> 7.340625
A10: Maintanance costs | E10: Maintanance costs
A11: Maintanance | B11: 3% of the installed capital cost | C11: =0.03*CAPEX!B57 -> 1.2072805 | E11: Maintanance | F11: 3% of the installed capital cost | G11: =0.03*CAPEX!C57 -> 1.6216311
C12: =C11 -> 1.2072805 | G12: =G11 -> 1.6216311
A13: Overhead expenses | E13: Overhead expenses
A14: Plant overhead | B14: 65% of labor and maintanace | C14: =0.65*(C6+C7+C8+C11) -> 5.5561386 | E14: Plant overhead | F14: 65% of labor and maintanace | G14: =0.65*(G6+G7+G8+G11) -> 5.8254665
A15: Tax & Insurance | B15: 2% of installed cost and offsites | C15: =0.02*(CAPEX!B57+CAPEX!B58) -> 1.0463098 | E15: Tax & Insurance | F15: 2% of installed cost and offsites | G15: =0.02*(CAPEX!C57+CAPEX!C58) -> 1.4054137
C16: =SUM(C14:C15) -> 6.6024484 | G16: =SUM(G14:G15) -> 7.2308801
A17: Interest | E17: Interest
A18: Interest on debit | B18: 6% of working capital | C18: =0.06*CAPEX!B62 -> 0.65917517 | E18: Interest on debit | F18: 6% of working capital | G18: =0.06*CAPEX!C62 -> 0.8854106
C19: =C18 -> 0.65917517 | G19: =G18 -> 0.8854106
A20: Total fixed production costs | C20: =C9+C12+C16+C19 -> 15.809529 | E20: Total fixed production costs | G20: =G9+G12+G16+G19 -> 17.078547

Sheet OPEX
B3: Material | C3: Unit | D3: Quantity | E3: Price 2019 ($/unit) | F3: Price 2022 ($/unit) | G3: 2019 costs | H3: 2022 costs
B4: Raw material costs
B5: Oxygen | C5: ton/hr | D5: 0 | E5: =123.25*C16/C15 -> 124.14919 | F5: =E5*C17/C16 -> 166.75841 | G5: =D5*E5 -> 0 | H5: =D5*F5 -> 0 | I5: =G5/Summary!$C$23 -> 0 | J5: =H5/Summary!$C$23 -> 0
B6: Ammonia fossil | C6: ton/hr | D6: =34060.001373291/1000 -> 34.060001 | E6: 465.07 | F6: 728.17 | G6: =D6*E6 -> 15840.285 | H6: =D6*F6 -> 24801.471 | I6: =G6/Summary!$C$23 -> 0.42225403 | J6: =H6/Summary!$C$23 -> 0.66113212
B7: Ammonia wind | C7: ton/hr | D7: =34060.001373291/1000 -> 34.060001 | E7: 1313.2 | F7: 1366.03 | G7: =D7*E7 -> 44727.594 | H7: =D7*F7 -> 46526.984 | I7: =G7/Summary!$C$23 -> 1.1923022 | J7: =H7/Summary!$C$23 -> 1.2402685
B8: Utility costs
B9: Cooling water | C9: GJ/hr | D9: =318203424.937963/10^6 -> 318.20342 | E9: 0.38 | F9: =E9*C17/C16 -> 0.51041975 | G9: =D9*E9 -> 120.9173 | H9: =D9*F9 -> 162.41731 | I9: =G9/Summary!$C$23 -> 0.0032232891 | J9: =H9/Summary!$C$23 -> 0.0043295538
B10: Electricity | C10: kWh | D10: 13933.004 | E10: 0.06783 | F10: 0.0853 | G10: =D10*E10 -> 945.07568 | H10: =D10*F10 -> 1188.4853 | I10: =G10/Summary!$C$23 -> 0.025192856 | J10: =H10/Summary!$C$23 -> 0.031681418
B11: OPEX (fossil ammonia) | C11: M$/year | G11: =(G5+G6+G9+G10)/1000000*8000 -> 135.25022 | H11: =(H5+H6+H9+H10)/1000000*8000 -> 209.21899
B12: OPEX (wind ammonia) | C12: M$/year | G12: =(G5+G7+G9+G10)/1000000*8000 -> 366.34869 | H12: =(H5+H7+H9+H10)/1000000*8000 -> 383.02309
B14: Reference Data
B15: CEPCI 2018 | C15: 603.1
B16: CEPCI 2019 | C16: 607.5
B17: CEPCI 2022 | C17: 816

Sheet Summary
B2: Fossil ammonia 2019 | E2: Fossil ammonia 2022 | H2: Wind ammonia 2019 | K2: Wind ammonia 2022
B3: Purchased equipment cost 2019 (M$/year) | C3: =SUM(CAPEX!B53) -> 10.760076 | E3: Purchased equipment cost 2022 (M$/year) | F3: =CAPEX!B54 -> 14.45304 | H3: Purchased equipment cost 2019 (M$/year) | I3: =C3 -> 10.760076 | K3: Purchased equipment cost 2022 (M$/year) | L3: =F3 -> 14.45304
B4: Installed capital cost | C4: =SUM(CAPEX!B57) -> 40.242684 | E4: Installed capital cost | F4: =CAPEX!C57 -> 54.054371 | H4: Installed capital cost | I4: =C4 -> 40.242684 | K4: Installed capital cost | L4: =F4 -> 54.054371
B5: Offsites (OS) | C5: =SUM(CAPEX!B58) -> 12.072805 | E5: Offsites (OS) | F5: =CAPEX!C58 -> 16.216311 | H5: Offsites (OS) | I5: =C5 -> 12.072805 | K5: Offsites (OS) | L5: =F5 -> 16.216311
B6: Design and engineering (D&E) | C6: =SUM(CAPEX!B59) -> 15.694647 | E6: Design and engineering (D&E) | F6: =CAPEX!C59 -> 21.081205 | H6: Design and engineering (D&E) | I6: =C6 -> 15.694647 | K6: Design and engineering (D&E) | L6: =F6 -> 21.081205
B7: Contingency (X) | C7: =SUM(CAPEX!B60) -> 5.231549 | E7: Contingency (X) | F7: =CAPEX!C60 -> 7.0270683 | H7: Contingency (X) | I7: =C7 -> 5.231549 | K7: Contingency (X) | L7: =F7 -> 7.0270683
B8: Fixed capital investment | C8: =SUM(CAPEX!B61) -> 73.241686 | E8: Fixed capital investment | F8: =CAPEX!C61 -> 98.378956 | H8: Fixed capital investment | I8: =C8 -> 73.241686 | K8: Fixed capital investment | L8: =F8 -> 98.378956
B9: Working capital | C9: =SUM(CAPEX!B62) -> 10.986253 | E9: Working capital | F9: =CAPEX!C62 -> 14.756843 | H9: Working capital | I9: =C9 -> 10.986253 | K9: Working capital | L9: =F9 -> 14.756843
B10: Total investment | C10: =SUM(CAPEX!B63) -> 84.227938 | E10: Total investment | F10: =CAPEX!C63 -> 113.1358 | H10: Total investment | I10: =C10 -> 84.227938 | K10: Total investment | L10: =F10 -> 113.1358
B11: Labor costs | C11: 0 | E11: Labor costs | F11: =SUM('Production costs'!F9) -> 0 | H11: Labor costs | I11: =C11 -> 0 | K11: Labor costs | L11: =F11 -> 0
B12: Maintanance costs | C12: 0 | E12: Maintanance costs | F12: =SUM('Production costs'!F12) -> 0 | H12: Maintanance costs | I12: =C12 -> 0 | K12: Maintanance costs | L12: =F12 -> 0
B13: Overhead expenses | C13: 0 | E13: Overhead expenses | F13: =SUM('Production costs'!F16) -> 0 | H13: Overhead expenses | I13: =C13 -> 0 | K13: Overhead expenses | L13: =F13 -> 0
B14: Interest | C14: 0 | E14: Interest | F14: =SUM('Production costs'!F19) -> 0 | H14: Interest | I14: =C14 -> 0 | K14: Interest | L14: =F14 -> 0
B15: Project lifetime | C15: =SUM(CAPEX!B64) -> 25 | E15: Project lifetime | F15: 25 | H15: Project lifetime | I15: =C15 -> 25 | K15: Project lifetime | L15: =F15 -> 25
B16: Interest rate | C16: =SUM(CAPEX!B65) -> 0.12 | E16: Interest rate | F16: 0.12 | H16: Interest rate | I16: =C16 -> 0.12 | K16: Interest rate | L16: =F16 -> 0.12
B17: ACCR | C17: =SUM(CAPEX!B66) -> 0.12749997 | E17: ACCR | F17: 0.12749997 | H17: ACCR | I17: =C17 -> 0.12749997 | K17: ACCR | L17: =F17 -> 0.12749997
B18: CAPEX (M$/year) | C18: =SUM(CAPEX!B68) -> 10.73906 | E18: CAPEX (M$/year) | F18: =CAPEX!C68 -> 14.424811 | H18: CAPEX (M$/year) | I18: =C18 -> 10.73906 | K18: CAPEX (M$/year) | L18: =F18 -> 14.424811
B19: Fixed production costs (M$/year) | C19: 0 | E19: Fixed production costs (M$/year) | F19: 0 | H19: Fixed production costs (M$/year) | I19: 0 | K19: Fixed production costs (M$/year) | L19: 0
B20: OPEX (M$/year) | C20: =OPEX!G11 -> 135.25022 | E20: OPEX (M$/year) | F20: =OPEX!H11 -> 209.21899 | H20: OPEX (M$/year) | I20: =OPEX!G12 -> 366.34869 | K20: OPEX (M$/year) | L20: =OPEX!H12 -> 383.02309
B21: Total expenses (M$/year) | C21: =(C18+C19+C20) -> 145.98928 | E21: Total expenses (M$/year) | F21: =(F18+F19+F20) -> 223.6438 | H21: Total expenses (M$/year) | I21: =(I18+I19+I20) -> 377.08775 | K21: Total expenses (M$/year) | L21: =(L18+L19+L20) -> 397.4479
B22: Total expenses ($/hr) | C22: =(C21)*1000000/8000 -> 18248.66 | E22: Total expenses ($/hr) | F22: =(F21)*1000000/8000 -> 27955.475 | H22: Total expenses ($/hr) | I22: =(I21)*1000000/8000 -> 47135.969 | K22: Total expenses ($/hr) | L22: =(L21)*1000000/8000 -> 49680.988
B23: Total product Produced (kg/hr) | C23: 37513.638 | E23: Total product Produced (kg/hr) | F23: 37513.638 | H23: Total product Produced (kg/hr) | I23: 37513.638 | K23: Total product Produced (kg/hr) | L23: 37513.638
B24: Cost per kg | C24: =C22/C23 -> 0.48645402 | E24: Cost per kg | F24: =F22/F23 -> 0.74520831 | H24: Cost per kg | I24: =I22/I23 -> 1.2565022 | K24: Cost per kg | L24: =L22/L23 -> 1.3243447
I26: =I18*10^6/8000/I23 -> 0.035783851 | L26: =L18*10^6/8000/L23 -> 0.048065222
