Workbook

Sheet CAPEX
A1: Cost factors
A2: Equipment erection | B2: fer | C2: 0.3
A3: Piping | B3: fp | C3: 0.8
A4: Instrumentation and control | B4: fi | C4: 0.3
A5: Electrical | B5: fel | C5: 0.2
A6: Civil | B6: fc | C6: 0.3
A7: Structures and buildings | B7: fs | C7: 0.2
A8: Lagging and paint | B8: fl | C8: 0.1
A9: Material factor for 304 SS | B9: fm | C9: 1.3
A12: Equipment | B12: Equipment approximated as | C12: Dimension needed | D12: Value | E12: a | F12: b | G12: n | H12: Purchased Cost (Ce,i,a) | L12: Equipment | M12: Internal diameter (m) | N12: h (m) | O12: External diameter (m) | P12: Area for shell (m2) | Q12: Volume | R12: Density (kg/m3) | S12: Shell mass (kg)
A13: Compressors | L13: B3 | M13: 1.6764 | N13: =4.7244+2*0.25*M13 -> 5.5626 | O13: =M13+0.0254 -> 1.7018 | P13: =PI()*(O13*O13-M13*M13)/4 -> 0.067392095 | Q13: =P13*N13 -> 0.37487527 | R13: 8000 | S13: =R13*Q13 -> 2999.0021
A14: K-100 | B14: Centrifugal Compressor | C14: Power, kW | D14: 1611.169 | E14: 580000 | F14: 20000 | G14: 0.6 | H14: =(E14+(F14*(D14^G14)))/1000000 -> 2.2600208 | L14: B6 | M14: 1.524 | N14: =3.6576+2*0.25*M14 -> 4.4196 | O14: =M14+0.0254 -> 1.5494 | P14: =PI()*(O14*O14-M14*M14)/4 -> 0.061311605 | Q14: =P14*N14 -> 0.27097277 | R14: 8000 | S14: =R14*Q14 -> 2167.7822
A15: K-100 | B15: Centrifugal Compressor | C15: Power, kW | D15: 609.46197 | E15: 580000 | F15: 20000 | G15: 0.6 | H15: =(E15+(F15*(D15^G15)))/1000000 -> 1.5175576 | L15: Reactor | M15: =M13 -> 1.6764 | N15: =N13 -> 5.5626 | O15: =M15+0.0254 -> 1.7018 | P15: =PI()*(O15*O15-M15*M15)/4 -> 0.067392095 | Q15: =P15*N15 -> 0.37487527 | R15: 8000 | S15: =R15*Q15 -> 2999.0021
A16: K-100 | B16: Centrifugal Compressor | C16: Power, kW | D16: 312.07412 | E16: 580000 | F16: 20000 | G16: 0.6 | H16: =(E16+(F16*(D16^G16)))/1000000 -> 1.207458 | L16: B9 | M16: 0.9144 | N16: =3.6576+2*0.25*M16 -> 4.1148 | O16: =M16+0.0254 -> 0.9398 | P16: =PI()*(O16*O16-M16*M16)/4 -> 0.036989646 | Q16: =P16*N16 -> 0.152205 | R16: 8000 | S16: =R16*Q16 -> 1217.64
A17: K-100 | B17: Centrifugal Compressor | C17: Power, kW | D17: 117.88417 | E17: 580000 | F17: 20000 | G17: 0.6 | H17: =(E17+(F17*(D17^G17)))/1000000 -> 0.92986725 | L17: B16 | M17: 0.9144 | N17: =3.6576+2*0.25*M17 -> 4.1148 | O17: =M17+0.0254 -> 0.9398 | P17: =PI()*(O17*O17-M17*M17)/4 -> 0.036989646 | Q17: =P17*N17 -> 0.152205 | R17: 8000 | S17: =R17*Q17 -> 1217.64
A18: K-100 | B18: Centrifugal Compressor | C18: Power, kW | D18: 243.73997 | E18: 580000 | F18: 20000 | G18: 0.6 | H18: =(E18+(F18*(D18^G18)))/1000000 -> 1.120986 | L18: B13 | M18: 0.9144 | N18: =3.6576+2*0.25*M18 -> 4.1148 | O18: =M18+0.0254 -> 0.9398 | P18: =PI()*(O18*O18-M18*M18)/4 -> 0.036989646 | Q18: =P18*N18 -> 0.152205 | R18: 8000 | S18: =R18*Q18 -> 1217.64
A19: K-100 | B19: Centrifugal Compressor | C19: Power, kW | D19: 92.924514 | E19: 580000 | F19: 20000 | G19: 0.6 | H19: =(E19+(F19*(D19^G19)))/1000000 -> 0.88332498 | L19: B14 | M19: 0.9144 | N19: =3.6576+2*0.25*M19 -> 4.1148 | O19: =M19+0.0254 -> 0.9398 | P19: =PI()*(O19*O19-M19*M19)/4 -> 0.036989646 | Q19: =P19*N19 -> 0.152205 | R19: 8000 | S19: =R19*Q19 -> 1217.64
A20: Heat exchangers
A21: E-100 | B21: U Tube HEX | C21: Area | D21: =I21/J21 -> 183.70956 | E21: 28000 | F21: 54 | G21: 1.2 | H21: =(E21+(F21*(D21^G21)))/1000000*J21 -> 0.1122836 | I21: 367.41912 | J21: 2
A22: E-101 | B22: U Tube HEX | C22: Area | D22: =I22/J22 -> 44.48807 | E22: 28000 | F22: 54 | G22: 1.2 | H22: =(E22+(F22*(D22^G22)))/1000000*J22 -> 0.066263986 | I22: 88.97614 | J22: 2
A23: E-102 | B23: U Tube HEX | C23: Area | D23: =I23/J23 -> 62.458796 | E23: 28000 | F23: 54 | G23: 1.2 | H23: =(E23+(F23*(D23^G23)))/1000000*J23 -> 0.071421836 | I23: 124.91759 | J23: 2
A24: E-103 | B24: U Tube HEX | C24: Area | D24: =I24/J24 -> 485.54931 | E24: 28000 | F24: 54 | G24: 1.2 | H24: =(E24+(F24*(D24^G24)))/1000000*J24 -> 1.7750803 | I24: 7283.2396 | J24: 15
A25: E-104 | B25: U Tube HEX | C25: Area | D25: =I25/J25 -> 478.28449 | E25: 28000 | F25: 54 | G25: 1.2 | H25: =(E25+(F25*(D25^G25)))/1000000*J25 -> 0.9337531 | I25: 3826.2759 | J25: 8
A26: E-105 | B26: U Tube HEX | C26: Area | D26: =I26/J26 -> 31.306769 | E26: 28000 | F26: 54 | G26: 1.2 | H26: =(E26+(F26*(D26^G26)))/1000000*J26 -> 0.062732706 | I26: 62.613539 | J26: 2
A27: E-106 | B27: U Tube HEX | C27: Area | D27: =I27/J27 -> 360.45839 | E27: 28000 | F27: 54 | G27: 1.2 | H27: =(E27+(F27*(D27^G27)))/1000000*J27 -> 0.18237173 | I27: 720.91678 | J27: 2
A28: Reactors
A29: CRV-100 | B29: Pressure vessel | C29: Shell mass, kg | D29: =S15 -> 2999.0021 | E29: 17400 | F29: 79 | G29: 0.85 | H29: =(E29+(F29*(D29^G29)))/1000000 -> 0.088694717
A30: Flash separators
A31: B3 | B31: Pressure vessel | C31: Shell mass, kg | D31: =S13 -> 2999.0021 | E31: 17400 | F31: 79 | G31: 0.85 | H31: =(E31+(F31*(D31^G31)))/1000000 -> 0.088694717
A32: B6 | B32: Pressure vessel | C32: Shell mass, kg | D32: =S14 -> 2167.7822 | E32: 17400 | F32: 79 | G32: 0.85 | H32: =(E32+(F32*(D32^G32)))/1000000 -> 0.071505371
B33: Pressure vessel | C33: Shell mass, kg | D33: =S16 -> 1217.64 | E33: 17400 | F33: 79 | G33: 0.85 | H33: =(E33+(F33*(D33^G33)))/1000000 -> 0.050537379
B34: Pressure vessel | C34: Shell mass, kg | D34: =S17 -> 1217.64 | E34: 17400 | F34: 79 | G34: 0.85 | H34: =(E34+(F34*(D34^G34)))/1000000 -> 0.050537379
B35: Pressure vessel | C35: Shell mass, kg | D35: =S18 -> 1217.64 | E35: 17400 | F35: 79 | G35: 0.85 | H35: =(E35+(F35*(D35^G35)))/1000000 -> 0.050537379
B36: Pressure vessel | C36: Shell mass, kg | D36: =S19 -> 1217.64 | E36: 17400 | F36: 79 | G36: 0.85 | H36: =(E36+(F36*(D36^G36)))/1000000 -> 0.050537379
H37: =SUM(H14:H36) -> 11.574166
A38: CEPCI 2010 | B38: 532.9
A39: CEPCI 2019 | B39: 607.5
A40: CEPCI 2022 | B40: 816
A41: Purchased equipment cost 2019 | B41: =H37*B39/B38 -> 13.194419
A42: Purchased equipment cost 2022 | B42: =H37*B40/B38 -> 17.722874
...

Sheet Production costs
A3: 2022
A4: Description | B4: Assumption | C4: M$/year
A5: Labor costs
A6: Operating labor | B6: 9 shift positions, 9 operators/shift | C6: =50000*9*9/1000000 -> 4.05
A7: Supervision | B7: 25% of operating Labor | C7: =0.25*C6 -> 1.0125
A8: Direct overhead | B8: 45% of labor and supervision | C8: =0.45*(C6+C7) -> 2.278125
C9: =SUM(C6:C8) -> 7.340625
A10: Maintanance costs
A11: Maintanance | B11: 3% of the installed capital cost | C11: =0.03*CAPEX!B45 -> 1.9885065
C12: =C11 -> 1.9885065
A13: Overhead expenses
A14: Plant overhead | B14: 65% of labor and maintanace | C14: =0.65*(C6+C7+C8+C11) -> 6.0639355
A15: Tax & Insurance | B15: 2% of installed cost and offsites | C15: =0.02*(CAPEX!B45+CAPEX!B46) -> 1.7233723
C16: =SUM(C14:C15) -> 7.7873077
A17: Interest
A18: Interest on debit | B18: 6% of working capital | C18: =0.06*CAPEX!B50 -> 1.0857245
C19: =C18 -> 1.0857245
A20: Total fixed production costs | C20: =C9+C12+C16+C19 -> 18.202164

Sheet OPEX
B3: Material | C3: Unit | D3: Quantity | E3: Price 2022 ($/unit) | F3: 2022 costs | I3: Ammonia price | J3: 2022 | K3: 2050
B4: Raw material costs | I4: Fossil | J4: 728.17 | K4: =J4*596.2/550.8*596.2/550.8*596.2/550.8 -> 923.47874
B5: Oxygen | C5: ton/hr | D5: 0 | E5: 0 | F5: =D5*E5 -> 0 | I5: Wind | J5: 1366.03 | K5: 925.28
B6: Ammonia fossil | C6: ton/hr | D6: 33.887005 | E6: 728.17 | F6: =D6*E6 -> 24675.5
B7: Ammonia wind | C7: ton/hr | D7: 33.887005 | E7: 1366.03 | F7: =D7*E7 -> 46290.665
B8: Utility costs | I8: 2022
B9: Cooling water | C9: GJ/hr | D9: 190.23636 | E9: =0.38*C18/C17 -> 0.51041975 | F9: =D9*E9 -> 97.100394 | I9: Ammonia price | J9: Fossil | K9: Wind
B10: Refrigerant to -150 °C | C10: GJ/hr | D10: 0 | E10: 194.11454 | F10: 0 | I10: Low | J10: 668.49 | K10: 1361.05
B11: Electricity | C11: kWh | D11: 2987.2537 | E11: =69.6/1000*C18/C17 -> 0.093487407 | F11: =D11*E11 -> 279.2706 | I11: High | J11: 789.66 | K11: 1370.63
B12: OPEX (fossil ammonia) | C12: M$/year | F12: =(F5+F6+F9+F10+F11)/1000000*8000 -> 200.41497
B13: OPEX (wind ammonia) | C13: M$/year | F13: =(F5+F7+F9+F10+F11)/1000000*8000 -> 373.33629 | I13: 2050
I14: Ammonia price | J14: Fossil | K14: Wind
B15: Reference Data | I15: Low | J15: =K4*0.85 -> 784.95693 | K15: 658.84
B16: CEPCI 2018 | C16: 603.1 | I16: High | J16: =K4*1.15 -> 1062.0006 | K16: 1191.73
B17: CEPCI 2019 | C17: 607.5
B18: CEPCI 2022 | C18: 816

Sheet Summary
B2: Fossil ammonia 2022 | F2: Wind ammonia 2022
B3: Purchased equipment cost 2022 (M$/year) | C3: =CAPEX!B42 -> 17.722874 | F3: Purchased equipment cost 2022 (M$/year) | G3: =C3 -> 17.722874
B4: Installed capital cost | C4: =CAPEX!B45 -> 66.283549 | F4: Installed capital cost | G4: =C4 -> 66.283549
B5: Offsites (OS) | C5: =CAPEX!B46 -> 19.885065 | F5: Offsites (OS) | G5: =C5 -> 19.885065
B6: Design and engineering (D&E) | C6: =CAPEX!B47 -> 25.850584 | F6: Design and engineering (D&E) | G6: =C6 -> 25.850584
B7: Contingency (X) | C7: =CAPEX!B48 -> 8.6168614 | F7: Contingency (X) | G7: =C7 -> 8.6168614
B8: Fixed capital investment | C8: =CAPEX!B49 -> 120.63606 | F8: Fixed capital investment | G8: =C8 -> 120.63606
B9: Working capital | C9: =CAPEX!B50 -> 18.095409 | F9: Working capital | G9: =C9 -> 18.095409
B10: Total investment | C10: =CAPEX!B51 -> 138.73147 | F10: Total investment | G10: =C10 -> 138.73147
B11: Labor costs | C11: =SUM('Production costs'!B9) -> 0 | F11: Labor costs | G11: =C11 -> 0
B12: Maintanance costs | C12: =SUM('Production costs'!B12) -> 0 | F12: Maintanance costs | G12: =C12 -> 0
B13: Overhead expenses | C13: =SUM('Production costs'!B16) -> 0 | F13: Overhead expenses | G13: =C13 -> 0
B14: Interest | C14: =SUM('Production costs'!B19) -> 0 | F14: Interest | G14: =C14 -> 0
B15: Project lifetime | C15: 25 | F15: Project lifetime | G15: =C15 -> 25
B16: Interest rate | C16: 0.12 | F16: Interest rate | G16: =C16 -> 0.12
B17: ACCR | C17: 0.12749997 | F17: ACCR | G17: =C17 -> 0.12749997
B18: CAPEX (M$/year) | C18: =CAPEX!B56 -> 17.688258 | F18: CAPEX (M$/year) | G18: =C18 -> 17.688258
B19: Fixed production costs (M$/year) | C19: 0 | F19: Fixed production costs (M$/year) | G19: 0
B20: OPEX (M$/year) | C20: =OPEX!F12 -> 200.41497 | F20: OPEX (M$/year) | G20: =OPEX!F13 -> 373.33629
B21: Total expenses (M$/year) | C21: =(C18+C19+C20) -> 218.10323 | F21: Total expenses (M$/year) | G21: =(G18+G19+G20) -> 391.02455
B22: Total expenses ($/hr) | C22: =(C21)*1000000/8000 -> 27262.904 | F22: Total expenses ($/hr) | G22: =(G21)*1000000/8000 -> 48878.068
B23: Total product Produced (kg/hr) | C23: 37500 | F23: Total product Produced (kg/hr) | G23: 37500
B24: Cost per kg | C24: =C22/C23 -> 0.72701076 | F24: Cost per kg | G24: =G22/G23 -> 1.3034152
