Workbook

Sheet CAPEX
A1: Cost factors
A2: Equipment erection | B2: fer | C2: 0.3
A3: Piping | B3: fp | C3: 0.8
A4: Instrumentation and control | B4: fi | C4: 0.3
A5: Electrical | B5: fel | C5: 0.2
A6: Civil | B6: fc | C6: 0.3
A7: Structures and buildings | B7: fs | C7: 0.2
A8: Lagging and paint | B8: fl | C8: 0.1
A9: Material factor for 304 SS | B9: fm | C9: 1.3
A12: Equipment | B12: Equipment approximated as | C12: Dimension needed | D12: Value | E12: a | F12: b | G12: n | H12: Purchased Cost (Ce,i,a) | J12: Equipment | K12: Internal diameter (m) | L12: h (m) | M12: External diameter (m) | N12: Area for shell (m2) | O12: Volume | P12: Density (kg/m3) | Q12: Shell mass (kg)
A13: Compressors | J13: V-100 | K13: 3.048 | L13: 10.668 | M13: =K13+0.0254 -> 3.0734 | N13: =PI()*(M13*M13-K13*K13)/4 -> 0.1221165 | O13: =N13*L13 -> 1.3027388 | P13: 8000 | Q13: =P13*O13 -> 10421.911
A14: K-100 | B14: Centrifugal Compressor | C14: Power, kW | D14: 1484.8999 | E14: 580000 | F14: 20000 | G14: 0.6 | H14: =(E14+(F14*(D14^G14)))/1000000 -> 2.1797359 | J14: V-101 | K14: 3.048 | L14: 10.668 | M14: =K14+0.0254 -> 3.0734 | N14: =PI()*(M14*M14-K14*K14)/4 -> 0.1221165 | O14: =N14*L14 -> 1.3027388 | P14: 8000 | Q14: =P14*O14 -> 10421.911
A15: K-101 | B15: Centrifugal Compressor | C15: Power, kW | D15: 656.83464 | E15: 580000 | F15: 20000 | G15: 0.6 | H15: =(E15+(F15*(D15^G15)))/1000000 -> 1.5606265 | J15: V-102 | K15: 2.8956 | L15: 10.1346 | M15: =K15+0.0254 -> 2.921 | N15: =PI()*(M15*M15-K15*K15)/4 -> 0.11603601 | O15: =N15*L15 -> 1.1759786 | P15: 8000 | Q15: =P15*O15 -> 9407.8286
A16: K-102 | B16: Centrifugal Compressor | C16: Power, kW | D16: 1041.6036 | E16: 580000 | F16: 20000 | G16: 0.6 | H16: =(E16+(F16*(D16^G16)))/1000000 -> 1.8731577 | J16: CRV-100 | K16: 3.048 | L16: 10.668 | M16: =K16+0.0254 -> 3.0734 | N16: =PI()*(M16*M16-K16*K16)/4 -> 0.1221165 | O16: =N16*L16 -> 1.3027388 | P16: 8000 | Q16: =P16*O16 -> 10421.911
A17: K-103 | B17: Centrifugal Compressor | C17: Power, kW | D17: 490.5462 | E17: 580000 | F17: 20000 | G17: 0.6 | H17: =(E17+(F17*(D17^G17)))/1000000 -> 1.4030722 | J17: CRV-101 | K17: 3.048 | L17: 10.668 | M17: =K17+0.0254 -> 3.0734 | N17: =PI()*(M17*M17-K17*K17)/4 -> 0.1221165 | O17: =N17*L17 -> 1.3027388 | P17: 8000 | Q17: =P17*O17 -> 10421.911
A18: Pumps | J18: CRV-102 | K18: 2.8956 | L18: 10.1346 | M18: =K18+0.0254 -> 2.921 | N18: =PI()*(M18*M18-K18*K18)/4 -> 0.11603601 | O18: =N18*L18 -> 1.1759786 | P18: 8000 | Q18: =P18*O18 -> 9407.8286
A19: P-100 | B19: Centrifugal Pump | C19: Flow, litres/s | D19: =16.6199752598893*1000/3600 -> 4.6166598 | E19: 8000 | F19: 240 | G19: 0.9 | H19: =(E19+(F19*(D19^G19)))/1000000 -> 0.0089508376
A20: Heat exchangers
A21: E-130 | B21: U Tube HEX | C21: Area | D21: 301.50825 | E21: 28000 | F21: 54 | G21: 1.2 | H21: =(E21+(F21*(D21^G21)))/1000000 -> 0.078997959
A22: E-117 | B22: U Tube HEX | C22: Area | D22: 55.793536 | E22: 28000 | F22: 54 | G22: 1.2 | H22: =(E22+(F22*(D22^G22)))/1000000 -> 0.034734331
A23: E-125 | B23: U Tube HEX | C23: Area | D23: 449.39485 | E23: 28000 | F23: 54 | G23: 1.2 | H23: 0.20835055
A24: E-129 | B24: U Tube HEX | C24: Area | D24: 200.94865 | E24: 28000 | F24: 54 | G24: 1.2 | H24: 0.20835055
A25: E-120 | B25: U Tube HEX | C25: Area | D25: =1935.57823888771/2 -> 967.78912 | E25: 28000 | F25: 54 | G25: 1.2 | H25: =(E25+(F25*(D25^G25)))/1000000 -> 0.23469532
A26: E-120 | B26: U Tube HEX | C26: Area | D26: =1935.57823888771/2 -> 967.78912 | E26: 28000 | F26: 54 | G26: 1.2 | H26: =(E26+(F26*(D26^G26)))/1000000 -> 0.23469532
A27: E-112 | B27: U Tube HEX | C27: Area | D27: 120.37542 | E27: 28000 | F27: 54 | G27: 1.2 | H27: =(E27+(F27*(D27^G27)))/1000000 -> 0.044944904
A28: E-122 | B28: U Tube HEX | C28: Area | D28: 104.99955 | E28: 28000 | F28: 54 | G28: 1.2 | H28: =(E28+(F28*(D28^G28)))/1000000 -> 0.042381981
A29: E-124 | B29: U Tube HEX | C29: Area | D29: 446.13787 | E29: 28000 | F29: 54 | G29: 1.2 | H29: =(E29+(F29*(D29^G29)))/1000000 -> 0.1096125
A30: E-126 | B30: U Tube HEX | C30: Area | D30: =7692.18386995348/8 -> 961.52298 | E30: 28000 | F30: 54 | G30: 1.2 | H30: =(E30+(F30*(D30^G30)))/1000000 -> 0.23309041
A31: E-126 | B31: U Tube HEX | C31: Area | D31: =7692.18386995348/8 -> 961.52298 | E31: 28000 | F31: 54 | G31: 1.2 | H31: =(E31+(F31*(D31^G31)))/1000000 -> 0.23309041
A32: E-126 | B32: U Tube HEX | C32: Area | D32: =7692.18386995348/8 -> 961.52298 | E32: 28000 | F32: 54 | G32: 1.2 | H32: =(E32+(F32*(D32^G32)))/1000000 -> 0.23309041
A33: E-126 | B33: U Tube HEX | C33: Area | D33: =7692.18386995348/8 -> 961.52298 | E33: 28000 | F33: 54 | G33: 1.2 | H33: =(E33+(F33*(D33^G33)))/1000000 -> 0.23309041
A34: E-126 | B34: U Tube HEX | C34: Area | D34: =7692.18386995348/8 -> 961.52298 | E34: 28000 | F34: 54 | G34: 1.2 | H34: =(E34+(F34*(D34^G34)))/1000000 -> 0.23309041
A35: E-126 | B35: U Tube HEX | C35: Area | D35: =7692.18386995348/8 -> 961.52298 | E35: 28000 | F35: 54 | G35: 1.2 | H35: =(E35+(F35*(D35^G35)))/1000000 -> 0.23309041
A36: E-126 | B36: U Tube HEX | C36: Area | D36: =7692.18386995348/8 -> 961.52298 | E36: 28000 | F36: 54 | G36: 1.2 | H36: =(E36+(F36*(D36^G36)))/1000000 -> 0.23309041
A37: E-126 | B37: U Tube HEX | C37: Area | D37: =7692.18386995348/8 -> 961.52298 | E37: 28000 | F37: 54 | G37: 1.2 | H37: =(E37+(F37*(D37^G37)))/1000000 -> 0.23309041
A38: E-128 | B38: U Tube HEX | C38: Area | D38: 152.63595 | E38: 28000 | F38: 54 | G38: 1.2 | H38: =(E38+(F38*(D38^G38)))/1000000 -> 0.050531077
A39: E-119 | B39: U Tube HEX | C39: Area | D39: =4335.13923558727/5 -> 867.02785 | E39: 28000 | F39: 54 | G39: 1.2 | H39: =(E39+(F39*(D39^G39)))/1000000 -> 0.20914795
A40: E-119 | B40: U Tube HEX | C40: Area | D40: =4335.13923558727/5 -> 867.02785 | E40: 28000 | F40: 54 | G40: 1.2 | H40: =(E40+(F40*(D40^G40)))/1000000 -> 0.20914795
A41: E-119 | B41: U Tube HEX | C41: Area | D41: =4335.13923558727/5 -> 867.02785 | E41: 28000 | F41: 54 | G41: 1.2 | H41: =(E41+(F41*(D41^G41)))/1000000 -> 0.20914795
A42: E-119 | B42: U Tube HEX | C42: Area | D42: =4335.13923558727/5 -> 867.02785 | E42: 28000 | F42: 54 | G42: 1.2 | H42: =(E42+(F42*(D42^G42)))/1000000 -> 0.20914795
...

Sheet Production costs
A3: 2019 | E3: 2022
A4: Description | B4: Assumption | C4: M$/year | E4: Description | F4: Assumption | G4: M$/year
A5: Labor costs | E5: Labor costs
A6: Operating labor | B6: 9 shift positions, 9 operators/shift | C6: =50000*9*9/1000000 -> 4.05 | E6: Operating labor | F6: 9 shift positions, 9 operators/shift | G6: =50000*9*9/1000000 -> 4.05
A7: Supervision | B7: 25% of operating Labor | C7: =0.25*C6 -> 1.0125 | E7: Supervision | F7: 25% of operating Labor | G7: =0.25*G6 -> 1.0125
A8: Direct overhead | B8: 45% of labor and supervision | C8: =0.45*(C6+C7) -> 2.278125 | E8: Direct overhead | F8: 45% of labor and supervision | G8: =0.45*(G6+G7) -> 2.278125
C9: =SUM(C6:C8) -> 7.340625 | G9: =SUM(G6:G8) -> 7.340625
A10: Maintanance costs | E10: Maintanance costs
A11: Maintanance | B11: 3% of the installed capital cost | C11: =0.03*CAPEX!B70 -> 1.7517892 | E11: Maintanance | F11: 3% of the installed capital cost | G11: =0.03*CAPEX!C70 -> 2.3530205
C12: =C11 -> 1.7517892 | G12: =G11 -> 2.3530205
A13: Overhead expenses | E13: Overhead expenses
A14: Plant overhead | B14: 65% of labor and maintanace | C14: =0.65*(C6+C7+C8+C11) -> 5.9100692 | E14: Plant overhead | F14: 65% of labor and maintanace | G14: =0.65*(G6+G7+G8+G11) -> 6.3008696
A15: Tax & Insurance | B15: 2% of installed cost and offsites | C15: =0.02*(CAPEX!B70+CAPEX!B71) -> 1.5182173 | E15: Tax & Insurance | F15: 2% of installed cost and offsites | G15: =0.02*(CAPEX!C70+CAPEX!C71) -> 2.0392845
C16: =SUM(C14:C15) -> 7.4282865 | G16: =SUM(G14:G15) -> 8.340154
A17: Interest | E17: Interest
A18: Interest on debit | B18: 6% of working capital | C18: =0.06*CAPEX!B75 -> 0.95647689 | E18: Interest on debit | F18: 6% of working capital | G18: =0.06*CAPEX!C75 -> 1.2847492
C19: =C18 -> 0.95647689 | G19: =G18 -> 1.2847492
A20: Total fixed production costs | C20: =C9+C12+C16+C19 -> 17.477178 | E20: Total fixed production costs | G20: =G9+G12+G16+G19 -> 19.318549

Sheet OPEX
B3: Material | C3: Unit | D3: Quantity | E3: Price 2019 ($/unit) | F3: Price 2022 ($/unit) | G3: 2019 costs | H3: 2022 costs
B4: Raw material costs
B5: Oxygen | C5: ton/hr | D5: =61417.92/1000 -> 61.41792 | E5: =123.25*C16/C15 -> 124.14919 | F5: =E5*C17/C16 -> 166.75841 | G5: =D5*E5 -> 7624.9849 | H5: =D5*F5 -> 10241.955
B6: Ammonia fossil | C6: ton/hr | D6: =33113.1562779304/1000 -> 33.113156 | E6: 400.43 | F6: 1517.81 | G6: =D6*E6 -> 13259.501 | H6: =D6*F6 -> 50259.48
B7: Ammonia wind | C7: ton/hr | D7: =33113.1562779304/1000 -> 33.113156 | E7: 1435.02 | F7: 1480.35 | G7: =D7*E7 -> 47518.042 | H7: =D7*F7 -> 49019.061
B8: Utility costs
B9: Cooling water | C9: GJ/hr | D9: =312885731.164979/10^6 -> 312.88573 | E9: 0.38 | F9: =E9*C17/C16 -> 0.51041975 | G9: =D9*E9 -> 118.89658 | H9: =D9*F9 -> 159.70306
B10: Electricity | C10: kWh | D10: 3678.1532 | E10: =37.7/1000 -> 0.0377 | F10: =235.28/1000 -> 0.23528 | G10: =D10*E10 -> 138.66638 | H10: =D10*F10 -> 865.39589
B11: OPEX (fossil ammonia) | C11: M$/year | G11: =(G5+G6+G9+G10)/1000000*8000 -> 169.13639 | H11: =(H5+H6+H9+H10)/1000000*8000 -> 492.21227
B12: OPEX (wind ammonia) | C12: M$/year | G12: =(G5+G7+G9+G10)/1000000*8000 -> 443.20471 | H12: =(H5+H7+H9+H10)/1000000*8000 -> 482.28892
B14: Reference Data
B15: CEPCI 2018 | C15: 603.1
B16: CEPCI 2019 | C16: 607.5
B17: CEPCI 2022 | C17: 816

Sheet Summary
B2: Fossil ammonia 2019 | E2: Fossil ammonia 2022 | H2: Wind ammonia 2019 | K2: Wind ammonia 2022
B3: Purchased equipment cost 2019 (M$/year) | C3: =SUM(CAPEX!B66) -> 15.613094 | E3: Purchased equipment cost 2022 (M$/year) | F3: =CAPEX!B67 -> 20.971662 | H3: Purchased equipment cost 2019 (M$/year) | I3: =C3 -> 15.613094 | K3: Purchased equipment cost 2022 (M$/year) | L3: =F3 -> 20.971662
B4: Installed capital cost | C4: =SUM(CAPEX!B70) -> 58.392973 | E4: Installed capital cost | F4: =CAPEX!C70 -> 78.434017 | H4: Installed capital cost | I4: =C4 -> 58.392973 | K4: Installed capital cost | L4: =F4 -> 78.434017
B5: Offsites (OS) | C5: =SUM(CAPEX!B71) -> 17.517892 | E5: Offsites (OS) | F5: =CAPEX!C71 -> 23.530205 | H5: Offsites (OS) | I5: =C5 -> 17.517892 | K5: Offsites (OS) | L5: =F5 -> 23.530205
B6: Design and engineering (D&E) | C6: =SUM(CAPEX!B72) -> 22.773259 | E6: Design and engineering (D&E) | F6: =CAPEX!C72 -> 30.589267 | H6: Design and engineering (D&E) | I6: =C6 -> 22.773259 | K6: Design and engineering (D&E) | L6: =F6 -> 30.589267
B7: Contingency (X) | C7: =SUM(CAPEX!B73) -> 7.5910864 | E7: Contingency (X) | F7: =CAPEX!C73 -> 10.196422 | H7: Contingency (X) | I7: =C7 -> 7.5910864 | K7: Contingency (X) | L7: =F7 -> 10.196422
B8: Fixed capital investment | C8: =SUM(CAPEX!B74) -> 106.27521 | E8: Fixed capital investment | F8: =CAPEX!C74 -> 142.74991 | H8: Fixed capital investment | I8: =C8 -> 106.27521 | K8: Fixed capital investment | L8: =F8 -> 142.74991
B9: Working capital | C9: =SUM(CAPEX!B75) -> 15.941282 | E9: Working capital | F9: =CAPEX!C75 -> 21.412487 | H9: Working capital | I9: =C9 -> 15.941282 | K9: Working capital | L9: =F9 -> 21.412487
B10: Total investment | C10: =SUM(CAPEX!B76) -> 122.21649 | E10: Total investment | F10: =CAPEX!C76 -> 164.1624 | H10: Total investment | I10: =C10 -> 122.21649 | K10: Total investment | L10: =F10 -> 164.1624
B11: Labor costs | C11: 0 | E11: Labor costs | F11: =SUM('Production costs'!F9) -> 0 | H11: Labor costs | I11: =C11 -> 0 | K11: Labor costs | L11: =F11 -> 0
B12: Maintanance costs | C12: 0 | E12: Maintanance costs | F12: =SUM('Production costs'!F12) -> 0 | H12: Maintanance costs | I12: =C12 -> 0 | K12: Maintanance costs | L12: =F12 -> 0
B13: Overhead expenses | C13: 0 | E13: Overhead expenses | F13: =SUM('Production costs'!F16) -> 0 | H13: Overhead expenses | I13: =C13 -> 0 | K13: Overhead expenses | L13: =F13 -> 0
B14: Interest | C14: 0 | E14: Interest | F14: =SUM('Production costs'!F19) -> 0 | H14: Interest | I14: =C14 -> 0 | K14: Interest | L14: =F14 -> 0
B15: Project lifetime | C15: =SUM(CAPEX!B77) -> 25 | E15: Project lifetime | F15: 25 | H15: Project lifetime | I15: =C15 -> 25 | K15: Project lifetime | L15: =F15 -> 25
B16: Interest rate | C16: =SUM(CAPEX!B78) -> 0.12 | E16: Interest rate | F16: 0.12 | H16: Interest rate | I16: =C16 -> 0.12 | K16: Interest rate | L16: =F16 -> 0.12
B17: ACCR | C17: =SUM(CAPEX!B79) -> 0.12749997 | E17: ACCR | F17: 0.12749997 | H17: ACCR | I17: =C17 -> 0.12749997 | K17: ACCR | L17: =F17 -> 0.12749997
B18: CAPEX (M$/year) | C18: =SUM(CAPEX!B81) -> 15.582599 | E18: CAPEX (M$/year) | F18: =CAPEX!C81 -> 20.930701 | H18: CAPEX (M$/year) | I18: =C18 -> 15.582599 | K18: CAPEX (M$/year) | L18: =F18 -> 20.930701
B19: Fixed production costs (M$/year) | C19: 0 | E19: Fixed production costs (M$/year) | F19: 0 | H19: Fixed production costs (M$/year) | I19: 0 | K19: Fixed production costs (M$/year) | L19: 0
B20: OPEX (M$/year) | C20: =OPEX!G11 -> 169.13639 | E20: OPEX (M$/year) | F20: =OPEX!H11 -> 492.21227 | H20: OPEX (M$/year) | I20: =OPEX!G12 -> 443.20471 | K20: OPEX (M$/year) | L20: =OPEX!H12 -> 482.28892
B21: Total expenses (M$/year) | C21: =(C18+C19+C20) -> 184.71899 | E21: Total expenses (M$/year) | F21: =(F18+F19+F20) -> 513.14297 | H21: Total expenses (M$/year) | I21: =(I18+I19+I20) -> 458.78731 | K21: Total expenses (M$/year) | L21: =(L18+L19+L20) -> 503.21962
B22: Total expenses ($/hr) | C22: =(C21)*1000000/8000 -> 23089.874 | E22: Total expenses ($/hr) | F22: =(F21)*1000000/8000 -> 64142.871 | H22: Total expenses ($/hr) | I22: =(I21)*1000000/8000 -> 57348.414 | K22: Total expenses ($/hr) | L22: =(L21)*1000000/8000 -> 62902.452
B23: Total product Produced (kg/hr) | C23: 40379.08 | E23: Total product Produced (kg/hr) | F23: 40379.08 | H23: Total product Produced (kg/hr) | I23: 40379.08 | K23: Total product Produced (kg/hr) | L23: 40379.08
B24: Cost per kg | C24: =C22/C23 -> 0.57182764 | E24: Cost per kg | F24: =F22/F23 -> 1.5885174 | H24: Cost per kg | I24: =I22/I23 -> 1.4202506 | K24: Cost per kg | L24: =L22/L23 -> 1.5577981
