Workbook

Sheet CAPEX
A1: Cost factors
A2: Equipment erection | B2: fer | C2: 0.3
A3: Piping | B3: fp | C3: 0.8
A4: Instrumentation and control | B4: fi | C4: 0.3
A5: Electrical | B5: fel | C5: 0.2
A6: Civil | B6: fc | C6: 0.3
A7: Structures and buildings | B7: fs | C7: 0.2
A8: Lagging and paint | B8: fl | C8: 0.1
A9: Material factor for 304 SS | B9: fm | C9: 1.3
A12: Equipment | B12: Equipment approximated as | C12: Dimension needed | D12: Value | E12: a | F12: b | G12: n | H12: Purchased Cost (Ce,i,a) | J12: Equipment | K12: Internal diameter (m) | L12: h (m) | M12: External diameter (m) | N12: Area for shell (m2) | O12: Volume | P12: Density (kg/m3) | Q12: Shell mass (kg)
A13: Compressors | J13: V-100 | K13: 1.6764 | L13: =4.7244+2*0.25*K13 -> 5.5626 | M13: =K13+0.0254 -> 1.7018 | N13: =PI()*(M13*M13-K13*K13)/4 -> 0.067392095 | O13: =N13*L13 -> 0.37487527 | P13: 8000 | Q13: =P13*O13 -> 2999.0021
A14: K-100 | B14: Centrifugal Compressor | C14: Power, kW | D14: 1366.5031 | E14: 580000 | F14: 20000 | G14: 0.6 | H14: =(E14+(F14*(D14^G14)))/1000000 -> 2.1019359 | J14: V-101 | K14: 1.3716 | L14: =3.6576+2*0.25*K14 -> 4.3434 | M14: =K14+0.0254 -> 1.397 | N14: =PI()*(M14*M14-K14*K14)/4 -> 0.055231115 | O14: =N14*L14 -> 0.23989083 | P14: 8000 | Q14: =P14*O14 -> 1919.1266
A15: K-101 | B15: Centrifugal Compressor | C15: Power, kW | D15: 518.80827 | E15: 580000 | F15: 20000 | G15: 0.6 | H15: =(E15+(F15*(D15^G15)))/1000000 -> 1.4312049 | J15: CRV-100 | K15: 1.6764 | L15: =4.7244+2*0.25*K15 -> 5.5626 | M15: =K15+0.0254 -> 1.7018 | N15: =PI()*(M15*M15-K15*K15)/4 -> 0.067392095 | O15: =N15*L15 -> 0.37487527 | P15: 8000 | Q15: =P15*O15 -> 2999.0021
A16: Heat exchangers
A17: E-103 | B17: U Tube HEX | C17: Area | D17: =I17/J17 -> 298.77984 | E17: 28000 | F17: 54 | G17: 1.2 | H17: =(E17+(F17*(D17^G17)))/1000000*J17 -> 0.15688934 | I17: 597.55968 | J17: 2
A18: E-105 | B18: U Tube HEX | C18: Area | D18: =I18/J18 -> 499.27777 | E18: 28000 | F18: 54 | G18: 1.2 | H18: =(E18+(F18*(D18^G18)))/1000000*J18 -> 1.5783609 | I18: 6490.6111 | J18: 13
A19: E-102 | B19: U Tube HEX | C19: Area | D19: =I19/J19 -> 419.54922 | E19: 28000 | F19: 54 | G19: 1.2 | H19: =(E19+(F19*(D19^G19)))/1000000*J19 -> 0.83048944 | I19: 3356.3937 | J19: 8
A20: E-104 | B20: U Tube HEX | C20: Area | D20: =I20/J20 -> 286.42402 | E20: 28000 | F20: 54 | G20: 1.2 | H20: =(E20+(F20*(D20^G20)))/1000000*J20 -> 0.075951819 | I20: 286.42402 | J20: 1
A21: Reactors
A22: CRV-100 | B22: Pressure vessel | C22: Shell mass, kg | D22: =Q15 -> 2999.0021 | E22: 17400 | F22: 79 | G22: 0.85 | H22: =(E22+(F22*(D22^G22)))/1000000 -> 0.088694717
A23: Flash separators
A24: V-100 | B24: Pressure vessel | C24: Shell mass, kg | D24: =Q13 -> 2999.0021 | E24: 17400 | F24: 79 | G24: 0.85 | H24: =(E24+(F24*(D24^G24)))/1000000 -> 0.088694717
A25: V-101 | B25: Pressure vessel | C25: Shell mass, kg | D25: =Q14 -> 1919.1266 | E25: 17400 | F25: 79 | G25: 0.85 | H25: =(E25+(F25*(D25^G25)))/1000000 -> 0.066182626
H26: =SUM(H14:H25) -> 6.4184044
A27: CEPCI 2010 | B27: 532.9
A28: CEPCI 2019 | B28: 607.5
A29: CEPCI 2022 | B29: 816
A30: Purchased equipment cost 2019 | B30: =H26*B28/B27 -> 7.3169088
A31: Purchased equipment cost 2022 | B31: =H26*B29/B27 -> 9.8281441
B33: 2019 | C33: 2022
A34: Installed capital cost | B34: =(B30)*((1+C3)+(C2+C5+C4+C6+C7+C8)/C9)*C9 -> 27.365239 | C34: =(B31)*((1+C3)+(C2+C5+C4+C6+C7+C8)/C9)*C9 -> 36.757259
A35: Offsites (OS) | B35: =0.3*B34 -> 8.2095716 | C35: =0.3*C34 -> 11.027178
A36: Design and Engineering (D&E) | B36: =0.3*SUM(B34:B35) -> 10.672443 | C36: =0.3*SUM(C34:C35) -> 14.335331
A37: Contingency (X) | B37: =0.1*SUM(B34:B35) -> 3.557481 | C37: =0.1*SUM(C34:C35) -> 4.7784437
A38: Fixed capital investment | B38: =B34*(1+0.3)*(1+0.3+0.1) -> 49.804735 | C38: =C34*(1+0.3)*(1+0.3+0.1) -> 66.898212
A39: Working capital | B39: =B38*0.15 -> 7.4707102 | C39: =C38*0.15 -> 10.034732
A40: Total investment | B40: =B38+B39 -> 57.275445 | C40: =C38+C39 -> 76.932943
A41: Project lifetime | B41: 25 | C41: 25
A42: Interest rate | B42: 0.12 | C42: 0.12
A43: ACCR | B43: =(B42*((1+B42)^B41))/(((1+B42)^B41)-1) -> 0.12749997 | C43: =(C42*((1+C42)^C41))/(((1+C42)^C41)-1) -> 0.12749997
...

Sheet Production costs
A3: 2019 | E3: 2022
A4: Description | B4: Assumption | C4: M$/year | E4: Description | F4: Assumption | G4: M$/year
A5: Labor costs | E5: Labor costs
A6: Operating labor | B6: 9 shift positions, 9 operators/shift | C6: =50000*9*9/1000000 -> 4.05 | E6: Operating labor | F6: 9 shift positions, 9 operators/shift | G6: =50000*9*9/1000000 -> 4.05
A7: Supervision | B7: 25% of operating Labor | C7: =0.25*C6 -> 1.0125 | E7: Supervision | F7: 25% of operating Labor | G7: =0.25*G6 -> 1.0125
A8: Direct overhead | B8: 45% of labor and supervision | C8: =0.45*(C6+C7) -> 2.278125 | E8: Direct overhead | F8: 45% of labor and supervision | G8: =0.45*(G6+G7) -> 2.278125
C9: =SUM(C6:C8) -> 7.340625 | G9: =SUM(G6:G8) -> 7.340625
A10: Maintanance costs | E10: Maintanance costs
A11: Maintanance | B11: 3% of the installed capital cost | C11: =0.03*CAPEX!B34 -> 0.82095716 | E11: Maintanance | F11: 3% of the installed capital cost | G11: =0.03*CAPEX!C34 -> 1.1027178
C12: =C11 -> 0.82095716 | G12: =G11 -> 1.1027178
A13: Overhead expenses | E13: Overhead expenses
A14: Plant overhead | B14: 65% of labor and maintanace | C14: =0.65*(C6+C7+C8+C11) -> 5.3050284 | E14: Plant overhead | F14: 65% of labor and maintanace | G14: =0.65*(G6+G7+G8+G11) -> 5.4881728
A15: Tax & Insurance | B15: 2% of installed cost and offsites | C15: =0.02*(CAPEX!B34+CAPEX!B35) -> 0.71149621 | E15: Tax & Insurance | F15: 2% of installed cost and offsites | G15: =0.02*(CAPEX!C34+CAPEX!C35) -> 0.95568874
C16: =SUM(C14:C15) -> 6.0165246 | G16: =SUM(G14:G15) -> 6.4438615
A17: Interest | E17: Interest
A18: Interest on debit | B18: 6% of working capital | C18: =0.06*CAPEX!B39 -> 0.44824261 | E18: Interest on debit | F18: 6% of working capital | G18: =0.06*CAPEX!C39 -> 0.6020839
C19: =C18 -> 0.44824261 | G19: =G18 -> 0.6020839
A20: Total fixed production costs | C20: =C9+C12+C16+C19 -> 14.626349 | E20: Total fixed production costs | G20: =G9+G12+G16+G19 -> 15.489288

Sheet OPEX
B3: Material | C3: Unit | D3: Quantity | E3: Price 2019 ($/unit) | F3: Price 2022 ($/unit) | G3: 2019 costs | H3: 2022 costs
B4: Raw material costs
B5: Oxygen | C5: ton/hr | D5: 0 | E5: =123.25*C17/C16 -> 124.14919 | F5: =E5*C18/C17 -> 166.75841 | G5: =D5*E5 -> 0 | H5: =D5*F5 -> 0 | I5: =G5/Summary!$C$23 -> 0 | J5: =H5/Summary!$C$23 -> 0
B6: Ammonia fossil | C6: ton/hr | D6: =30690.5025430649/1000 -> 30.690503 | E6: 465.07 | F6: 728.17 | G6: =D6*E6 -> 14273.232 | H6: =D6*F6 -> 22347.903 | I6: =G6/Summary!$C$23 -> 0.38061877 | J6: =H6/Summary!$C$23 -> 0.59594291
B7: Ammonia wind | C7: ton/hr | D7: =30690.5025430649/1000 -> 30.690503 | E7: 1313.2 | F7: 1366.03 | G7: =D7*E7 -> 40302.768 | H7: =D7*F7 -> 41924.147 | I7: =G7/Summary!$C$23 -> 1.0747384 | J7: =H7/Summary!$C$23 -> 1.117975
B8: Utility costs
B9: Cooling water | C9: GJ/hr | D9: =169540876.710415/1000000 -> 169.54088 | E9: 0.38 | F9: =E9*C18/C17 -> 0.51041975 | G9: =D9*E9 -> 64.425533 | H9: =D9*F9 -> 86.537012 | I9: =G9/Summary!$C$23 -> 0.0017180108 | J9: =H9/Summary!$C$23 -> 0.0023076491 | K9: =H9/Summary!$F$23 -> 0.0023076491
B10: Natural gas | C10: ton/hr | D10: 0 | E10: 67.83 | F10: 288.06 | G10: =D10*E10 -> 0 | H10: =D10*F10 -> 0 | I10: =G10/Summary!$C$23 -> 0 | J10: =H10/Summary!$C$23 -> 0 | K10: =H10/Summary!$F$23 -> 0
B11: Electricity | C11: kWh | D11: 1885.3113 | E11: 0.06783 | F11: 0.0853 | G11: =D11*E11 -> 127.88067 | H11: =D11*F11 -> 160.81706 | I11: =G11/Summary!$C$23 -> 0.0034101444 | J11: =H11/Summary!$C$23 -> 0.0042884463 | K11: =H11/Summary!$F$23 -> 0.0042884463
B12: OPEX (fossil ammonia) | C12: M$/year | G12: =(G5+G6+G9+G10+G11)/1000000*8000 -> 115.72431 | H12: =(H5+H6+H9+H10+H11)/1000000*8000 -> 180.76206
B13: OPEX (wind ammonia) | C13: M$/year | G13: =(G5+G7+G9+G10+G11)/1000000*8000 -> 323.96059 | H13: =(H5+H7+H9+H10+H11)/1000000*8000 -> 337.37201
B15: Reference Data
B16: CEPCI 2018 | C16: 603.1
B17: CEPCI 2019 | C17: 607.5
B18: CEPCI 2022 | C18: 816

Sheet Summary
B2: Fossil ammonia 2019 | E2: Fossil ammonia 2022 | H2: Wind ammonia 2019 | K2: Wind ammonia 2022
B3: Purchased equipment cost 2019 (M$/year) | C3: =SUM(CAPEX!B30) -> 7.3169088 | E3: Purchased equipment cost 2022 (M$/year) | F3: =CAPEX!B31 -> 9.8281441 | H3: Purchased equipment cost 2019 (M$/year) | I3: =C3 -> 7.3169088 | K3: Purchased equipment cost 2022 (M$/year) | L3: =F3 -> 9.8281441
B4: Installed capital cost | C4: =SUM(CAPEX!B34) -> 27.365239 | E4: Installed capital cost | F4: =CAPEX!C34 -> 36.757259 | H4: Installed capital cost | I4: =C4 -> 27.365239 | K4: Installed capital cost | L4: =F4 -> 36.757259
B5: Offsites (OS) | C5: =SUM(CAPEX!B35) -> 8.2095716 | E5: Offsites (OS) | F5: =CAPEX!C35 -> 11.027178 | H5: Offsites (OS) | I5: =C5 -> 8.2095716 | K5: Offsites (OS) | L5: =F5 -> 11.027178
B6: Design and engineering (D&E) | C6: =SUM(CAPEX!B36) -> 10.672443 | E6: Design and engineering (D&E) | F6: =CAPEX!C36 -> 14.335331 | H6: Design and engineering (D&E) | I6: =C6 -> 10.672443 | K6: Design and engineering (D&E) | L6: =F6 -> 14.335331
B7: Contingency (X) | C7: =SUM(CAPEX!B37) -> 3.557481 | E7: Contingency (X) | F7: =CAPEX!C37 -> 4.7784437 | H7: Contingency (X) | I7: =C7 -> 3.557481 | K7: Contingency (X) | L7: =F7 -> 4.7784437
B8: Fixed capital investment | C8: =SUM(CAPEX!B38) -> 49.804735 | E8: Fixed capital investment | F8: =CAPEX!C38 -> 66.898212 | H8: Fixed capital investment | I8: =C8 -> 49.804735 | K8: Fixed capital investment | L8: =F8 -> 66.898212
B9: Working capital | C9: =SUM(CAPEX!B39) -> 7.4707102 | E9: Working capital | F9: =CAPEX!C39 -> 10.034732 | H9: Working capital | I9: =C9 -> 7.4707102 | K9: Working capital | L9: =F9 -> 10.034732
B10: Total investment | C10: =SUM(CAPEX!B40) -> 57.275445 | E10: Total investment | F10: =CAPEX!C40 -> 76.932943 | H10: Total investment | I10: =C10 -> 57.275445 | K10: Total investment | L10: =F10 -> 76.932943
B11: Labor costs | C11: 0 | E11: Labor costs | F11: =SUM('Production costs'!F9) -> 0 | H11: Labor costs | I11: =C11 -> 0 | K11: Labor costs | L11: =F11 -> 0
B12: Maintanance costs | C12: 0 | E12: Maintanance costs | F12: =SUM('Production costs'!F12) -> 0 | H12: Maintanance costs | I12: =C12 -> 0 | K12: Maintanance costs | L12: =F12 -> 0
B13: Overhead expenses | C13: 0 | E13: Overhead expenses | F13: =SUM('Production costs'!F16) -> 0 | H13: Overhead expenses | I13: =C13 -> 0 | K13: Overhead expenses | L13: =F13 -> 0
B14: Interest | C14: 0 | E14: Interest | F14: =SUM('Production costs'!F19) -> 0 | H14: Interest | I14: =C14 -> 0 | K14: Interest | L14: =F14 -> 0
B15: Project lifetime | C15: =SUM(CAPEX!B41) -> 25 | E15: Project lifetime | F15: 25 | H15: Project lifetime | I15: =C15 -> 25 | K15: Project lifetime | L15: =F15 -> 25
B16: Interest rate | C16: =SUM(CAPEX!B42) -> 0.12 | E16: Interest rate | F16: 0.12 | H16: Interest rate | I16: =C16 -> 0.12 | K16: Interest rate | L16: =F16 -> 0.12
B17: ACCR | C17: =SUM(CAPEX!B43) -> 0.12749997 | E17: ACCR | F17: 0.12749997 | H17: ACCR | I17: =C17 -> 0.12749997 | K17: ACCR | L17: =F17 -> 0.12749997
B18: CAPEX (M$/year) | C18: =SUM(CAPEX!B45) -> 7.3026175 | E18: CAPEX (M$/year) | F18: =CAPEX!C45 -> 9.8089479 | H18: CAPEX (M$/year) | I18: =C18 -> 7.3026175 | K18: CAPEX (M$/year) | L18: =F18 -> 9.8089479
B19: Fixed production costs (M$/year) | C19: 0 | E19: Fixed production costs (M$/year) | F19: 0 | H19: Fixed production costs (M$/year) | I19: 0 | K19: Fixed production costs (M$/year) | L19: 0
B20: OPEX (M$/year) | C20: =OPEX!G12 -> 115.72431 | E20: OPEX (M$/year) | F20: =OPEX!H12 -> 180.76206 | H20: OPEX (M$/year) | I20: =OPEX!G13 -> 323.96059 | K20: OPEX (M$/year) | L20: =OPEX!H13 -> 337.37201
B21: Total expenses (M$/year) | C21: =(C18+C19+C20) -> 123.02692 | E21: Total expenses (M$/year) | F21: =(F18+F19+F20) -> 190.57101 | H21: Total expenses (M$/year) | I21: =(I18+I19+I20) -> 331.26321 | K21: Total expenses (M$/year) | L21: =(L18+L19+L20) -> 347.18096
B22: Total expenses ($/hr) | C22: =(C21)*1000000/8000 -> 15378.365 | E22: Total expenses ($/hr) | F22: =(F21)*1000000/8000 -> 23821.376 | H22: Total expenses ($/hr) | I22: =(I21)*1000000/8000 -> 41407.901 | K22: Total expenses ($/hr) | L22: =(L21)*1000000/8000 -> 43397.62
B23: Total product Produced (kg/hr) | C23: 37500.074 | E23: Total product Produced (kg/hr) | F23: =C23 -> 37500.074 | H23: Total product Produced (kg/hr) | I23: =F23 -> 37500.074 | K23: Total product Produced (kg/hr) | L23: =I23 -> 37500.074
B24: Cost per kg | C24: =C22/C23 -> 0.41008893 | E24: Cost per kg | F24: =F22/F23 -> 0.63523543 | H24: Cost per kg | I24: =I22/I23 -> 1.1042085 | K24: Cost per kg | L24: =L22/L23 -> 1.1572676
F26: =OPEX!H6/Summary!F23 -> 0.59594291 | I26: =I18*10^6/8000/I23 -> 0.02434201 | L26: =L18*10^6/8000/L23 -> 0.032696429
F27: =OPEX!H7/Summary!F23 -> 1.117975
F28: =F18*10^6/8000/F23 -> 0.032696429
